Workbook

Sheet 80109
B1: 商品センター | C1: 品番 | D1: 商品区分 | E1: カラー | F1: 72期 | G1: 73期 | H1: 74期(1期) | I1: 2023/10/1～2024/3/21（6か月） | J1: 75期(2期) | K1: 76期（３期 ） | L1: 77期（4期 7/1-12/18） | N1: 発注点 5ヶ月分なのでそのまま | O1: 在庫数 ロジザード | Q1: 入荷予定 ロジザード | S1: 確保数 弥生(在庫確保) | T1: 確保数チェック 0じゃなかったらロジザード修正 | U1: 有効数量 フリー在庫の数 | V1: 発注検討フラグ マイナスの場合発注検討 | W1: 在庫回転率 | X1: 前回決定事項（12/26） | Y1: 決定事項 | AE1: 前回決定事項（/） | AG1: 決定事項
A2: 1 | B2: 伊賀 | C2: APL-4312SBL | D2: ミニホイッスル付LEDアルミライトⅡ | H2: 192 | I2: =VLOOKUP(C2,'202310-202403出荷数total2403220951'!B:F,5,0) -> 71 | J2: =VLOOKUP(C2,'出荷数2307～2406total241008110618'!B:F,5,0) -> 281 | K2: =VLOOKUP(C2,'出荷数2407-2506total250730101950'!B:F,5,0) -> 902 | L2: =VLOOKUP(C:C,total251219111800!B:F,5,0) -> 386 | N2: =L2 -> 386 | O2: 427 | P2: 710 | Q2: 0 | R2: 0 | S2: 550 | T2: 160 | U2: -123 | V2: -509 | W2: 0.33948989
A3: 2 | B3: 伊賀 | C3: APL-4312SPK | D3: ミニホイッスル付LEDアルミライトⅡ | H3: 2161 | I3: =VLOOKUP(C3,'202310-202403出荷数total2403220951'!B:F,5,0) -> 1018 | J3: =VLOOKUP(C3,'出荷数2307～2406total241008110618'!B:F,5,0) -> 1930 | K3: =VLOOKUP(C3,'出荷数2407-2506total250730101950'!B:F,5,0) -> 3388 | L3: =VLOOKUP(C:C,total251219111800!B:F,5,0) -> 903 | N3: =L3 -> 903 | O3: 2232 | P3: 1980 | Q3: 0 | R3: 0 | S3: 1830 | T3: 150 | U3: 402 | V3: -501 | W3: 0.21438746
A4: 86 | B4: 伊賀 | C4: ABO-08BL | D4: ミニホイッスル | E4: ブルー | F4: 527 | G4: 2107 | H4: 796 | I4: =VLOOKUP(C4,'202310-202403出荷数total2403220951'!B:F,5,0) -> 1409 | J4: =VLOOKUP(C4,'出荷数2307～2406total241008110618'!B:F,5,0) -> 1708 | K4: =VLOOKUP(C4,'出荷数2407-2506total250730101950'!B:F,5,0) -> 1865 | L4: =VLOOKUP(C:C,total251219111800!B:F,5,0) -> 474 | M4: 1000 | N4: 1000 | O4: 6783 | P4: 0 | Q4: 0 | R4: 0 | S4: 0 | T4: 0 | U4: 6783 | V4: 5783 | W4: 0.14742739
A5: 107 | B5: 伊賀 | C5: ABO-08PK | D5: ミニホイッスル | E5: ピンク | F5: 3939 | G5: 5966 | H5: 5009 | I5: =VLOOKUP(C5,'202310-202403出荷数total2403220951'!B:F,5,0) -> 6490 | J5: =VLOOKUP(C5,'出荷数2307～2406total241008110618'!B:F,5,0) -> 17931 | K5: =VLOOKUP(C5,'出荷数2407-2506total250730101950'!B:F,5,0) -> 28387 | L5: =VLOOKUP(C:C,total251219111800!B:F,5,0) -> 4495 | N5: =L5 -> 4495 | O5: 31370 | P5: 35250 | Q5: 800 | R5: 0 | S5: 35250 | T5: 0 | U5: -3080 | V5: -7575 | W5: 0.067472231
A6: 109 | B6: 伊賀 | C6: APL-4302S | D6: ＬＥＤミニアルミライト | F6: 1094 | G6: 3475 | H6: 834 | I6: =VLOOKUP(C6,'202310-202403出荷数total2403220951'!B:F,5,0) -> 444 | J6: =VLOOKUP(C6,'出荷数2307～2406total241008110618'!B:F,5,0) -> 789 | K6: =VLOOKUP(C6,'出荷数2407-2506total250730101950'!B:F,5,0) -> 232 | L6: =VLOOKUP(C:C,total251219111800!B:F,5,0) -> 177 | N6: =L6 -> 177 | O6: 3754 | P6: 0 | Q6: 300 | R6: 0 | S6: 0 | T6: 0 | U6: 4054 | V6: 3877 | W6: 0.047149707
A7: 3 | B7: 伊賀 | C7: ASL-3308SK | D7: ウォールセンサーライト 箱 | E7: しかく | F7: 1 | G7: 0 | H7: 4 | I7: =VLOOKUP(C7,'202310-202403出荷数total2403220951'!B:F,5,0) -> #N/A | J7: =VLOOKUP(C7,'出荷数2307～2406total241008110618'!B:F,5,0) -> #N/A | K7: =VLOOKUP(C7,'出荷数2407-2506total250730101950'!B:F,5,0) -> #N/A | L7: =VLOOKUP(C:C,total251219111800!B:F,5,0) -> #N/A | N7: 0 | O7: 1 | P7: 0 | Q7: 0 | R7: 0 | S7: 0 | T7: 0 | U7: 1 | V7: 1 | W7: 0
A8: 4 | B8: 伊賀 | C8: AHL-3201RD | D8: LEDハンディライト | H8: 2048 | I8: =VLOOKUP(C8,'202310-202403出荷数total2403220951'!B:F,5,0) -> 2098 | J8: =VLOOKUP(C8,'出荷数2307～2406total241008110618'!B:F,5,0) -> 3644 | K8: =VLOOKUP(C8,'出荷数2407-2506total250730101950'!B:F,5,0) -> 2910 | L8: =VLOOKUP(C:C,total251219111800!B:F,5,0) -> 2559 | N8: =L8 -> 2559 | O8: 3061 | P8: 0 | Q8: 0 | R8: 0 | S8: 0 | T8: 0 | U8: 3061 | V8: 502 | W8: 0.83600131
A9: 5 | B9: 伊賀 | C9: AHL-3201WH | D9: LEDハンディライト | H9: 116 | I9: =VLOOKUP(C9,'202310-202403出荷数total2403220951'!B:F,5,0) -> 220 | J9: =VLOOKUP(C9,'出荷数2307～2406total241008110618'!B:F,5,0) -> 378 | K9: =VLOOKUP(C9,'出荷数2407-2506total250730101950'!B:F,5,0) -> 2016 | L9: =VLOOKUP(C:C,total251219111800!B:F,5,0) -> 281 | M9: 1000 | N9: 1000 | O9: 5196 | P9: 0 | Q9: 0 | R9: 0 | S9: 0 | T9: 0 | U9: 5196 | V9: 4196 | W9: 0.19245574
A10: 6 | B10: 伊賀 | C10: AHL-1400 | D10: LED強力ライト | H10: 15126 | I10: =VLOOKUP(C10,'202310-202403出荷数total2403220951'!B:F,5,0) -> 9163 | J10: =VLOOKUP(C10,'出荷数2307～2406total241008110618'!B:F,5,0) -> 19757 | K10: =VLOOKUP(C10,'出荷数2407-2506total250730101950'!B:F,5,0) -> 20812 | L10: =VLOOKUP(C:C,total251219111800!B:F,5,0) -> 4356 | N10: =L10 -> 4356 | O10: 2929 | P10: 13545 | Q10: 0 | R10: 0 | S10: 13175 | T10: 370 | U10: -10246 | V10: -14602 | W10: 0.26441666
A11: 7 | B11: 伊賀 | C11: AHL-1400T | D11: LED強力ライト(トップ) | H11: 2084 | I11: =VLOOKUP(C11,'202310-202403出荷数total2403220951'!B:F,5,0) -> 1160 | J11: =VLOOKUP(C11,'出荷数2307～2406total241008110618'!B:F,5,0) -> 1821 | K11: =VLOOKUP(C11,'出荷数2407-2506total250730101950'!B:F,5,0) -> 1120 | L11: =VLOOKUP(C:C,total251219111800!B:F,5,0) -> 160 | N11: =L11 -> 160 | O11: 2 | P11: 0 | Q11: 0 | R11: 0 | S11: 0 | T11: 0 | U11: 2 | V11: -158 | W11: 80
A12: 8 | B12: 伊賀 | C12: ASL-3308KU | D12: ウォールセンサーライト 箱 | E12: くも | F12: 193 | G12: 1 | H12: 100 | I12: =VLOOKUP(C12,'202310-202403出荷数total2403220951'!B:F,5,0) -> 43 | J12: =VLOOKUP(C12,'出荷数2307～2406total241008110618'!B:F,5,0) -> 51 | K12: =VLOOKUP(C12,'出荷数2407-2506total250730101950'!B:F,5,0) -> 12 | L12: =VLOOKUP(C:C,total251219111800!B:F,5,0) -> 3 | N12: =L12 -> 3 | O12: 999 | P12: 0 | Q12: 0 | R12: 0 | S12: 0 | T12: 0 | U12: 999 | V12: 996 | W12: 0.003003003
A13: 9 | B13: 伊賀 | C13: ANS-502 | D13: テレビ用手もとスピーカー | G13: 6 | H13: 2364 | I13: =VLOOKUP(C13,'202310-202403出荷数total2403220951'!B:F,5,0) -> 1052 | J13: =VLOOKUP(C13,'出荷数2307～2406total241008110618'!B:F,5,0) -> 1711 | K13: =VLOOKUP(C13,'出荷数2407-2506total250730101950'!B:F,5,0) -> 1026 | L13: =VLOOKUP(C:C,total251219111800!B:F,5,0) -> 587 | N13: =L13 -> 587 | O13: 3558 | P13: 0 | Q13: 0 | R13: 0 | S13: 0 | T13: 0 | U13: 3558 | V13: 2971 | W13: 0.16498033
A14: 10 | B14: 伊賀 | C14: ASL-3308US | D14: ウォールセンサーライト 箱 | E14: うさぎ | F14: 0 | G14: 3 | H14: 363 | I14: =VLOOKUP(C14,'202310-202403出荷数total2403220951'!B:F,5,0) -> #N/A | J14: =VLOOKUP(C14,'出荷数2307～2406total241008110618'!B:F,5,0) -> 1 | K14: =VLOOKUP(C14,'出荷数2407-2506total250730101950'!B:F,5,0) -> 7 | L14: =VLOOKUP(C:C,total251219111800!B:F,5,0) -> #N/A | N14: 0 | O14: 744 | P14: 0 | Q14: 0 | R14: 0 | S14: 0 | T14: 0 | U14: 744 | V14: 744 | W14: 0
A15: 11 | B15: 伊賀 | C15: ASL-3308CSK | D15: ウォールセンサーライト ブリスター | E15: しかく | F15: 23 | G15: 4 | H15: 0 | I15: =VLOOKUP(C15,'202310-202403出荷数total2403220951'!B:F,5,0) -> 1 | J15: =VLOOKUP(C15,'出荷数2307～2406total241008110618'!B:F,5,0) -> 705 | K15: =VLOOKUP(C15,'出荷数2407-2506total250730101950'!B:F,5,0) -> 1 | L15: =VLOOKUP(C:C,total251219111800!B:F,5,0) -> 1 | N15: =L15 -> 1 | O15: 0 | P15: 0 | Q15: 0 | R15: 0 | S15: 0 | T15: 0 | U15: 0 | V15: -1 | W15: #DIV/0!
A16: 12 | B16: 伊賀 | C16: ASL-3308CUS | D16: ウォールセンサーライト ブリスター | E16: うさぎ | F16: 35 | G16: 26 | H16: 5 | I16: =VLOOKUP(C16,'202310-202403出荷数total2403220951'!B:F,5,0) -> 3 | J16: =VLOOKUP(C16,'出荷数2307～2406total241008110618'!B:F,5,0) -> 6 | K16: =VLOOKUP(C16,'出荷数2407-2506total250730101950'!B:F,5,0) -> 3 | L16: =VLOOKUP(C:C,total251219111800!B:F,5,0) -> 142 | N16: =L16 -> 142 | O16: 4414 | P16: 0 | Q16: 0 | R16: 0 | S16: 0 | T16: 0 | U16: 4414 | V16: 4272 | W16: 0.032170367
A17: 13 | B17: 伊賀 | C17: AKM-3205PK | D17: 首ふり毛だまクリーナー | E17: ピンク | F17: 33 | G17: 24 | H17: 2990 | I17: =VLOOKUP(C17,'202310-202403出荷数total2403220951'!B:F,5,0) -> 66 | J17: =VLOOKUP(C17,'出荷数2307～2406total241008110618'!B:F,5,0) -> 189 | K17: =VLOOKUP(C17,'出荷数2407-2506total250730101950'!B:F,5,0) -> 97 | L17: =VLOOKUP(C:C,total251219111800!B:F,5,0) -> 77 | N17: =L17 -> 77 | O17: 2106 | P17: 0 | Q17: 0 | R17: 0 | S17: 0 | T17: 0 | U17: 2106 | V17: 2029 | W17: 0.036562203
A18: 14 | B18: 伊賀 | C18: ASN-4302 | D18: マグネット付ＬＥＤ信号灯 | F18: 149 | G18: 62 | H18: 132 | I18: =VLOOKUP(C18,'202310-202403出荷数total2403220951'!B:F,5,0) -> 245 | J18: =VLOOKUP(C18,'出荷数2307～2406total241008110618'!B:F,5,0) -> 322 | K18: =VLOOKUP(C18,'出荷数2407-2506total250730101950'!B:F,5,0) -> 206 | L18: =VLOOKUP(C:C,total251219111800!B:F,5,0) -> 17 | N18: =L18 -> 17 | O18: 2259 | P18: 0 | Q18: 0 | R18: 0 | S18: 0 | T18: 0 | U18: 2259 | V18: 2242 | W18: 0.0075254537 | X18: 売り切り廃盤予定 | Y18: 売り切り廃盤予定
A19: 15 | B19: 伊賀 | C19: AIC-01IV | D19: ｷｽﾞつきにくいｲｽ脚ｶﾊﾞｰ | E19: IV | F19: 228 | G19: 270 | H19: 231 | I19: =VLOOKUP(C19,'202310-202403出荷数total2403220951'!B:F,5,0) -> 121 | J19: =VLOOKUP(C19,'出荷数2307～2406total241008110618'!B:F,5,0) -> 177 | K19: =VLOOKUP(C19,'出荷数2407-2506total250730101950'!B:F,5,0) -> 110 | L19: =VLOOKUP(C:C,total251219111800!B:F,5,0) -> 53 | N19: =L19 -> 53 | O19: 8060 | P19: 0 | Q19: 0 | R19: 0 | S19: 0 | T19: 0 | U19: 8060 | V19: 8007 | W19: 0.0065756824
A20: 16 | B20: 伊賀 | C20: ANS-603 | D20: お経の流れるスピーカーⅡ | G20: 128 | H20: 470 | I20: =VLOOKUP(C20,'202310-202403出荷数total2403220951'!B:F,5,0) -> 149 | J20: =VLOOKUP(C20,'出荷数2307～2406total241008110618'!B:F,5,0) -> 418 | K20: =VLOOKUP(C20,'出荷数2407-2506total250730101950'!B:F,5,0) -> 818 | L20: =VLOOKUP(C:C,total251219111800!B:F,5,0) -> 491 | N20: =L20 -> 491 | O20: 617 | P20: 130 | Q20: 0 | R20: 0 | S20: 280 | T20: -150 | U20: 337 | V20: -154 | W20: 0.65729585 | X20: 様子見 | Y20: トップ確保3月末まで確保
A21: 17 | B21: 伊賀 | C21: APY-105 | D21: 迷惑電話お断りピンポン | F21: 543 | G21: 321 | H21: 270 | I21: =VLOOKUP(C21,'202310-202403出荷数total2403220951'!B:F,5,0) -> 73 | J21: =VLOOKUP(C21,'出荷数2307～2406total241008110618'!B:F,5,0) -> 181 | K21: =VLOOKUP(C21,'出荷数2407-2506total250730101950'!B:F,5,0) -> 277 | L21: =VLOOKUP(C:C,total251219111800!B:F,5,0) -> 141 | N21: =L21 -> 141 | O21: 3326 | P21: 370 | Q21: 0 | R21: 0 | S21: 370 | T21: 0 | U21: 2956 | V21: 2815 | W21: 0.038149351
A22: 18 | B22: 伊賀 | C22: APL-3207S | D22: LEDのインテリア常備灯 | F22: 904 | G22: 638 | H22: 81 | I22: =VLOOKUP(C22,'202310-202403出荷数total2403220951'!B:F,5,0) -> 2 | J22: =VLOOKUP(C22,'出荷数2307～2406total241008110618'!B:F,5,0) -> 904 | K22: =VLOOKUP(C22,'出荷数2407-2506total250730101950'!B:F,5,0) -> 25 | L22: =VLOOKUP(C:C,total251219111800!B:F,5,0) -> 2 | N22: =L22 -> 2 | O22: 6861 | P22: 0 | Q22: 0 | R22: 0 | S22: 0 | T22: 0 | U22: 6861 | V22: 6859 | W22: 0.0002915027
A23: 19 | B23: 伊賀 | C23: ALA-4308BK-D | D23: ひっぱり点灯ライト 電球色ＬＥＤ | F23: 1137 | G23: 270 | H23: 272 | I23: =VLOOKUP(C23,'202310-202403出荷数total2403220951'!B:F,5,0) -> 153 | J23: =VLOOKUP(C23,'出荷数2307～2406total241008110618'!B:F,5,0) -> 657 | K23: =VLOOKUP(C23,'出荷数2407-2506total250730101950'!B:F,5,0) -> 101 | L23: =VLOOKUP(C:C,total251219111800!B:F,5,0) -> 88 | N23: =L23 -> 88 | O23: 1782 | P23: 0 | Q23: 0 | R23: 0 | S23: 0 | T23: 0 | U23: 1782 | V23: 1694 | W23: 0.049382716
A24: 20 | B24: 伊賀 | C24: ACA-101 | D24: ＬＥＤ帽子ライト | F24: 787 | G24: 450 | H24: 417 | I24: =VLOOKUP(C24,'202310-202403出荷数total2403220951'!B:F,5,0) -> 450 | J24: =VLOOKUP(C24,'出荷数2307～2406total241008110618'!B:F,5,0) -> 550 | K24: =VLOOKUP(C24,'出荷数2407-2506total250730101950'!B:F,5,0) -> 160 | L24: =VLOOKUP(C:C,total251219111800!B:F,5,0) -> 89 | N24: =L24 -> 89 | O24: 3706 | P24: 0 | Q24: 0 | R24: 0 | S24: 0 | T24: 0 | U24: 3706 | V24: 3617 | W24: 0.024015111
A25: 21 | B25: 伊賀 | C25: ASL-3308NE | D25: ウォールセンサーライト 箱 | E25: ねこ | F25: 13 | G25: 4 | H25: 8 | I25: =VLOOKUP(C25,'202310-202403出荷数total2403220951'!B:F,5,0) -> 1 | J25: =VLOOKUP(C25,'出荷数2307～2406total241008110618'!B:F,5,0) -> 4 | K25: =VLOOKUP(C25,'出荷数2407-2506total250730101950'!B:F,5,0) -> 6 | L25: =VLOOKUP(C:C,total251219111800!B:F,5,0) -> #N/A | N25: 0 | O25: 24 | P25: 0 | Q25: 0 | R25: 0 | S25: 0 | T25: 0 | U25: 24 | V25: 24 | W25: 0
A26: 22 | B26: 伊賀 | C26: AKD-20 | D26: アニマルシリコンバンド | F26: 1809 | G26: 790 | H26: 1042 | I26: =VLOOKUP(C26,'202310-202403出荷数total2403220951'!B:F,5,0) -> 164 | J26: =VLOOKUP(C26,'出荷数2307～2406total241008110618'!B:F,5,0) -> 312 | K26: =VLOOKUP(C26,'出荷数2407-2506total250730101950'!B:F,5,0) -> 454 | L26: =VLOOKUP(C:C,total251219111800!B:F,5,0) -> 168 | N26: =L26 -> 168 | O26: 5727 | P26: 300 | Q26: 0 | R26: 0 | S26: 300 | T26: 0 | U26: 5427 | V26: 5259 | W26: 0.027874564
A27: 23 | B27: 伊賀 | C27: ARA-4301 | D27: スマートフォンが使えるラジオライト | F27: 549 | G27: 303 | H27: 236 | I27: =VLOOKUP(C27,'202310-202403出荷数total2403220951'!B:F,5,0) -> 241 | J27: =VLOOKUP(C27,'出荷数2307～2406total241008110618'!B:F,5,0) -> 358 | K27: =VLOOKUP(C27,'出荷数2407-2506total250730101950'!B:F,5,0) -> 392 | L27: =VLOOKUP(C:C,total251219111800!B:F,5,0) -> 29 | N27: =L27 -> 29 | O27: 1917 | P27: 0 | Q27: 0 | R27: 0 | S27: 0 | T27: 0 | U27: 1917 | V27: 1888 | W27: 0.015127804
A28: 24 | B28: 伊賀 | C28: ASK-11BOR | D28: 巻きつく安全反射バンド(OR) | E28: オレンジ | F28: 1160 | G28: 148 | H28: 651 | I28: =VLOOKUP(C28,'202310-202403出荷数total2403220951'!B:F,5,0) -> 60 | J28: =VLOOKUP(C28,'出荷数2307～2406total241008110618'!B:F,5,0) -> 125 | K28: =VLOOKUP(C28,'出荷数2407-2506total250730101950'!B:F,5,0) -> 265 | L28: =VLOOKUP(C:C,total251219111800!B:F,5,0) -> 38 | M28: 500 | N28: 500 | O28: 2313 | P28: 0 | Q28: 0 | R28: 0 | S28: 0 | T28: 0 | U28: 2313 | V28: 1813 | W28: 0.21616948
A29: 25 | B29: 伊賀 | C29: ASK-10YE | D29: 光るホイール反射シール | E29: イエロー | F29: 935 | G29: 77 | H29: 731 | I29: =VLOOKUP(C29,'202310-202403出荷数total2403220951'!B:F,5,0) -> 163 | J29: =VLOOKUP(C29,'出荷数2307～2406total241008110618'!B:F,5,0) -> 235 | K29: =VLOOKUP(C29,'出荷数2407-2506total250730101950'!B:F,5,0) -> 20 | L29: =VLOOKUP(C:C,total251219111800!B:F,5,0) -> 2 | N29: =L29 -> 2 | O29: 5 | P29: 0 | Q29: 0 | R29: 0 | S29: 0 | T29: 0 | U29: 5 | V29: 3 | W29: 0.4
A30: 26 | B30: 伊賀 | C30: ARO-530GD | D30: 自動消灯安心のろうそく | E30: GD | F30: 224 | G30: 198 | H30: 230 | I30: =VLOOKUP(C30,'202310-202403出荷数total2403220951'!B:F,5,0) -> 91 | J30: =VLOOKUP(C30,'出荷数2307～2406total241008110618'!B:F,5,0) -> 168 | K30: =VLOOKUP(C30,'出荷数2407-2506total250730101950'!B:F,5,0) -> 52 | L30: =VLOOKUP(C:C,total251219111800!B:F,5,0) -> 28 | N30: =L30 -> 28 | O30: 920 | P30: 0 | Q30: 0 | R30: 0 | S30: 0 | T30: 0 | U30: 920 | V30: 892 | W30: 0.030434783
A31: 27 | B31: 伊賀 | C31: ALA-4308MO-W | D31: ひっぱり点灯ライト 木目 | E31: 木目 | F31: 714 | G31: 368 | H31: 496 | I31: =VLOOKUP(C31,'202310-202403出荷数total2403220951'!B:F,5,0) -> 150 | J31: =VLOOKUP(C31,'出荷数2307～2406total241008110618'!B:F,5,0) -> 247 | K31: =VLOOKUP(C31,'出荷数2407-2506total250730101950'!B:F,5,0) -> 43 | L31: =VLOOKUP(C:C,total251219111800!B:F,5,0) -> 29 | N31: =L31 -> 29 | O31: 1947 | P31: 0 | Q31: 0 | R31: 0 | S31: 0 | T31: 0 | U31: 1947 | V31: 1918 | W31: 0.01489471
A32: 28 | B32: 伊賀 | C32: AIC-06IV | D32: ｽﾞﾚにくいｲｽ脚ｶﾊﾞｰ 2脚用 | E32: IV | F32: 1116 | G32: 928 | H32: 1098 | I32: =VLOOKUP(C32,'202310-202403出荷数total2403220951'!B:F,5,0) -> 427 | J32: =VLOOKUP(C32,'出荷数2307～2406total241008110618'!B:F,5,0) -> 1008 | K32: =VLOOKUP(C32,'出荷数2407-2506total250730101950'!B:F,5,0) -> 854 | L32: =VLOOKUP(C:C,total251219111800!B:F,5,0) -> 345 | N32: =L32 -> 345 | O32: 3124 | P32: 0 | Q32: 0 | R32: 0 | S32: 0 | T32: 0 | U32: 3124 | V32: 2779 | W32: 0.11043534 | X32: 88％発注点よりﾏｲﾅｽ 345→41 | Y32: 88％発注点よりﾏｲﾅｽ 345→41
A33: 29 | B33: 伊賀 | C33: ANS-701AD | D33: ＡＣアダプター701用 | F33: 120 | G33: 98 | H33: 141 | I33: =VLOOKUP(C33,'202310-202403出荷数total2403220951'!B:F,5,0) -> 41 | J33: =VLOOKUP(C33,'出荷数2307～2406total241008110618'!B:F,5,0) -> 89 | K33: =VLOOKUP(C33,'出荷数2407-2506total250730101950'!B:F,5,0) -> 92 | L33: =VLOOKUP(C:C,total251219111800!B:F,5,0) -> 49 | N33: =L33 -> 49 | O33: 319 | P33: 0 | Q33: 0 | R33: 0 | S33: 0 | T33: 0 | U33: 319 | V33: 270 | W33: 0.15360502
A34: 30 | B34: 伊賀 | C34: ANS-702 | D34: 大きな手もとスピーカー | F34: 1030 | G34: 390 | H34: 221 | I34: =VLOOKUP(C34,'202310-202403出荷数total2403220951'!B:F,5,0) -> 53 | J34: =VLOOKUP(C34,'出荷数2307～2406total241008110618'!B:F,5,0) -> 103 | K34: =VLOOKUP(C34,'出荷数2407-2506total250730101950'!B:F,5,0) -> 224 | L34: =VLOOKUP(C:C,total251219111800!B:F,5,0) -> 45 | N34: =L34 -> 45 | O34: 2078 | P34: 0 | Q34: 0 | R34: 0 | S34: 0 | T34: 0 | U34: 2078 | V34: 2033 | W34: 0.021655438
A35: 31 | B35: 伊賀 | C35: AKN-15 | D35: ハローキティ コンセントカバー | F35: 1322 | G35: 1075 | H35: 946 | I35: =VLOOKUP(C35,'202310-202403出荷数total2403220951'!B:F,5,0) -> 348 | J35: =VLOOKUP(C35,'出荷数2307～2406total241008110618'!B:F,5,0) -> 766 | K35: =VLOOKUP(C35,'出荷数2407-2506total250730101950'!B:F,5,0) -> 1074 | L35: =VLOOKUP(C:C,total251219111800!B:F,5,0) -> 327 | N35: =L35 -> 327 | O35: 3683 | P35: 0 | Q35: 0 | R35: 0 | S35: 0 | T35: 0 | U35: 3683 | V35: 3356 | W35: 0.088786316
A36: 32 | B36: 伊賀 | C36: ACA-3101 | D36: ＬＥＤアルミヘッドランプ | F36: 1781 | G36: 1472 | H36: 1360 | I36: =VLOOKUP(C36,'202310-202403出荷数total2403220951'!B:F,5,0) -> 3651 | J36: =VLOOKUP(C36,'出荷数2307～2406total241008110618'!B:F,5,0) -> 4452 | K36: =VLOOKUP(C36,'出荷数2407-2506total250730101950'!B:F,5,0) -> 4054 | L36: =VLOOKUP(C:C,total251219111800!B:F,5,0) -> 524 | N36: =L36 -> 524 | O36: 12996 | P36: 0 | Q36: 100 | R36: 0 | S36: 0 | T36: 0 | U36: 13096 | V36: 12572 | W36: 0.040320098
A37: 33 | B37: 伊賀 | C37: ASK-06SI | D37: はめるだけ光る 足腕バンド | E37: シルバー | F37: 1210 | G37: 214 | H37: 13 | I37: =VLOOKUP(C37,'202310-202403出荷数total2403220951'!B:F,5,0) -> 75 | J37: =VLOOKUP(C37,'出荷数2307～2406total241008110618'!B:F,5,0) -> 79 | K37: =VLOOKUP(C37,'出荷数2407-2506total250730101950'!B:F,5,0) -> 1 | L37: =VLOOKUP(C:C,total251219111800!B:F,5,0) -> 3 | N37: =L37 -> 3 | O37: 881 | P37: 0 | Q37: 0 | R37: 0 | S37: 0 | T37: 0 | U37: 881 | V37: 878 | W37: 0.0034052213
A38: 34 | B38: 伊賀 | C38: ASL-3308CNE | D38: ウォールセンサーライト ブリスター | E38: ねこ | F38: 271 | G38: 200 | H38: 124 | I38: =VLOOKUP(C38,'202310-202403出荷数total2403220951'!B:F,5,0) -> 63 | J38: =VLOOKUP(C38,'出荷数2307～2406total241008110618'!B:F,5,0) -> 93 | K38: =VLOOKUP(C38,'出荷数2407-2506total250730101950'!B:F,5,0) -> 14 | L38: =VLOOKUP(C:C,total251219111800!B:F,5,0) -> 140 | N38: =L38 -> 140 | O38: 797 | P38: 0 | Q38: 0 | R38: 0 | S38: 0 | T38: 0 | U38: 797 | V38: 657 | W38: 0.17565872
A39: 35 | B39: 伊賀 | C39: ASL-33082 | D39: ウォールセンサーライト（ショップチャンネル専用） | G39: 9 | H39: 1109 | I39: =VLOOKUP(C39,'202310-202403出荷数total2403220951'!B:F,5,0) -> #N/A | J39: =VLOOKUP(C39,'出荷数2307～2406total241008110618'!B:F,5,0) -> #N/A | K39: =VLOOKUP(C39,'出荷数2407-2506total250730101950'!B:F,5,0) -> #N/A | L39: =VLOOKUP(C:C,total251219111800!B:F,5,0) -> #N/A | M39: 470 | N39: 470 | O39: 106 | P39: 0 | Q39: 0 | R39: 0 | S39: 0 | T39: 0 | U39: 106 | V39: -364 | W39: 4.4339623
A40: 36 | B40: 伊賀 | C40: ADR-3401 | D40: 電動角質リムーバー | F40: 19 | G40: 1283 | H40: 7 | I40: =VLOOKUP(C40,'202310-202403出荷数total2403220951'!B:F,5,0) -> 223 | J40: =VLOOKUP(C40,'出荷数2307～2406total241008110618'!B:F,5,0) -> 598 | K40: =VLOOKUP(C40,'出荷数2407-2506total250730101950'!B:F,5,0) -> 73 | L40: =VLOOKUP(C:C,total251219111800!B:F,5,0) -> 5 | N40: =L40 -> 5 | O40: 4152 | P40: 0 | Q40: 0 | R40: 0 | S40: 0 | T40: 0 | U40: 4152 | V40: 4147 | W40: 0.0012042389
...

Sheet 80116
B1: 商品センター | C1: 品番 | D1: 商品区分 | E1: カラー | F1: 72期 | G1: 73期 | H1: 74期(1期) | I1: 2023/10/1～2024/3/21（6か月） | J1: 75期(2期) | K1: 76期（３期 ） | L1: 77期（4期 7/1-12/18） | N1: 発注点 5ヶ月分なのでそのまま | O1: 在庫数 ロジザード | Q1: 入荷予定 ロジザード | S1: 確保数 弥生(在庫確保) | T1: 確保数チェック 0じゃなかったらロジザード修正 | U1: 有効数量 フリー在庫の数 | V1: 発注検討フラグ マイナスの場合発注検討 | W1: 在庫回転率 | X1: 前回決定事項（1/9/） | Y1: 決定事項 | AE1: 前回決定事項（/） | AG1: 決定事項
A2: 1 | B2: 伊賀 | C2: APL-4312SBL | D2: ミニホイッスル付LEDアルミライトⅡ | H2: 192 | I2: =VLOOKUP(C2,'202310-202403出荷数total2403220951'!B:F,5,0) -> 71 | J2: =VLOOKUP(C2,'出荷数2307～2406total241008110618'!B:F,5,0) -> 281 | K2: =VLOOKUP(C2,'出荷数2407-2506total250730101950'!B:F,5,0) -> 902 | L2: =VLOOKUP(C:C,total251219111800!B:F,5,0) -> 386 | N2: =L2 -> 386 | O2: 427 | P2: 710 | Q2: 0 | R2: 0 | S2: 550 | T2: 160 | U2: -123 | V2: -509 | W2: 0.33948989
A3: 2 | B3: 伊賀 | C3: APL-4312SPK | D3: ミニホイッスル付LEDアルミライトⅡ | H3: 2161 | I3: =VLOOKUP(C3,'202310-202403出荷数total2403220951'!B:F,5,0) -> 1018 | J3: =VLOOKUP(C3,'出荷数2307～2406total241008110618'!B:F,5,0) -> 1930 | K3: =VLOOKUP(C3,'出荷数2407-2506total250730101950'!B:F,5,0) -> 3388 | L3: =VLOOKUP(C:C,total251219111800!B:F,5,0) -> 903 | N3: =L3 -> 903 | O3: 2082 | P3: 1980 | Q3: 0 | R3: 0 | S3: 1830 | T3: 150 | U3: 252 | V3: -651 | W3: 0.22230428
A4: 86 | B4: 伊賀 | C4: ABO-08BL | D4: ミニホイッスル | E4: ブルー | F4: 527 | G4: 2107 | H4: 796 | I4: =VLOOKUP(C4,'202310-202403出荷数total2403220951'!B:F,5,0) -> 1409 | J4: =VLOOKUP(C4,'出荷数2307～2406total241008110618'!B:F,5,0) -> 1708 | K4: =VLOOKUP(C4,'出荷数2407-2506total250730101950'!B:F,5,0) -> 1865 | L4: =VLOOKUP(C:C,total251219111800!B:F,5,0) -> 474 | M4: 1000 | N4: 1000 | O4: 6772 | P4: 0 | Q4: 0 | R4: 0 | S4: 0 | T4: 0 | U4: 6772 | V4: 5772 | W4: 0.14766686
A5: 107 | B5: 伊賀 | C5: ABO-08PK | D5: ミニホイッスル | E5: ピンク | F5: 3939 | G5: 5966 | H5: 5009 | I5: =VLOOKUP(C5,'202310-202403出荷数total2403220951'!B:F,5,0) -> 6490 | J5: =VLOOKUP(C5,'出荷数2307～2406total241008110618'!B:F,5,0) -> 17931 | K5: =VLOOKUP(C5,'出荷数2407-2506total250730101950'!B:F,5,0) -> 28387 | L5: =VLOOKUP(C:C,total251219111800!B:F,5,0) -> 4495 | N5: =L5 -> 4495 | O5: 31152 | P5: 35250 | Q5: 800 | R5: 0 | S5: 24430 | T5: 10820 | U5: 7522 | V5: 3027 | W5: 0.067693744
A6: 109 | B6: 伊賀 | C6: APL-4302S | D6: ＬＥＤミニアルミライト | F6: 1094 | G6: 3475 | H6: 834 | I6: =VLOOKUP(C6,'202310-202403出荷数total2403220951'!B:F,5,0) -> 444 | J6: =VLOOKUP(C6,'出荷数2307～2406total241008110618'!B:F,5,0) -> 789 | K6: =VLOOKUP(C6,'出荷数2407-2506total250730101950'!B:F,5,0) -> 232 | L6: =VLOOKUP(C:C,total251219111800!B:F,5,0) -> 177 | N6: =L6 -> 177 | O6: 3754 | P6: 0 | Q6: 300 | R6: 0 | S6: 0 | T6: 0 | U6: 4054 | V6: 3877 | W6: 0.047149707
A7: 3 | B7: 伊賀 | C7: ASL-3308SK | D7: ウォールセンサーライト 箱 | E7: しかく | F7: 1 | G7: 0 | H7: 4 | I7: =VLOOKUP(C7,'202310-202403出荷数total2403220951'!B:F,5,0) -> #N/A | J7: =VLOOKUP(C7,'出荷数2307～2406total241008110618'!B:F,5,0) -> #N/A | K7: =VLOOKUP(C7,'出荷数2407-2506total250730101950'!B:F,5,0) -> #N/A | L7: =VLOOKUP(C:C,total251219111800!B:F,5,0) -> #N/A | N7: 0 | O7: 1 | P7: 0 | Q7: 0 | R7: 0 | S7: 0 | T7: 0 | U7: 1 | V7: 1 | W7: 0
A8: 4 | B8: 伊賀 | C8: AHL-3201RD | D8: LEDハンディライト | H8: 2048 | I8: =VLOOKUP(C8,'202310-202403出荷数total2403220951'!B:F,5,0) -> 2098 | J8: =VLOOKUP(C8,'出荷数2307～2406total241008110618'!B:F,5,0) -> 3644 | K8: =VLOOKUP(C8,'出荷数2407-2506total250730101950'!B:F,5,0) -> 2910 | L8: =VLOOKUP(C:C,total251219111800!B:F,5,0) -> 2559 | N8: =L8 -> 2559 | O8: 3061 | P8: 0 | Q8: 0 | R8: 0 | S8: 0 | T8: 0 | U8: 3061 | V8: 502 | W8: 0.83600131
A9: 5 | B9: 伊賀 | C9: AHL-3201WH | D9: LEDハンディライト | H9: 116 | I9: =VLOOKUP(C9,'202310-202403出荷数total2403220951'!B:F,5,0) -> 220 | J9: =VLOOKUP(C9,'出荷数2307～2406total241008110618'!B:F,5,0) -> 378 | K9: =VLOOKUP(C9,'出荷数2407-2506total250730101950'!B:F,5,0) -> 2016 | L9: =VLOOKUP(C:C,total251219111800!B:F,5,0) -> 281 | M9: 1000 | N9: 1000 | O9: 5198 | P9: 0 | Q9: 0 | R9: 0 | S9: 0 | T9: 0 | U9: 5198 | V9: 4198 | W9: 0.19238169
A10: 6 | B10: 伊賀 | C10: AHL-1400 | D10: LED強力ライト | H10: 15126 | I10: =VLOOKUP(C10,'202310-202403出荷数total2403220951'!B:F,5,0) -> 9163 | J10: =VLOOKUP(C10,'出荷数2307～2406total241008110618'!B:F,5,0) -> 19757 | K10: =VLOOKUP(C10,'出荷数2407-2506total250730101950'!B:F,5,0) -> 20812 | L10: =VLOOKUP(C:C,total251219111800!B:F,5,0) -> 4356 | N10: =L10 -> 4356 | O10: 2676 | P10: 13545 | Q10: 0 | R10: 0 | S10: 13225 | T10: 320 | U10: -10549 | V10: -14905 | W10: 0.26854078
A11: 7 | B11: 伊賀 | C11: AHL-1400T | D11: LED強力ライト(トップ) | H11: 2084 | I11: =VLOOKUP(C11,'202310-202403出荷数total2403220951'!B:F,5,0) -> 1160 | J11: =VLOOKUP(C11,'出荷数2307～2406total241008110618'!B:F,5,0) -> 1821 | K11: =VLOOKUP(C11,'出荷数2407-2506total250730101950'!B:F,5,0) -> 1120 | L11: =VLOOKUP(C:C,total251219111800!B:F,5,0) -> 160 | N11: =L11 -> 160 | O11: 2 | P11: 0 | Q11: 0 | R11: 0 | S11: 0 | T11: 0 | U11: 2 | V11: -158 | W11: 80
A12: 8 | B12: 伊賀 | C12: ASL-3308KU | D12: ウォールセンサーライト 箱 | E12: くも | F12: 193 | G12: 1 | H12: 100 | I12: =VLOOKUP(C12,'202310-202403出荷数total2403220951'!B:F,5,0) -> 43 | J12: =VLOOKUP(C12,'出荷数2307～2406total241008110618'!B:F,5,0) -> 51 | K12: =VLOOKUP(C12,'出荷数2407-2506total250730101950'!B:F,5,0) -> 12 | L12: =VLOOKUP(C:C,total251219111800!B:F,5,0) -> 3 | N12: =L12 -> 3 | O12: 999 | P12: 0 | Q12: 0 | R12: 0 | S12: 0 | T12: 0 | U12: 999 | V12: 996 | W12: 0.003003003
A13: 9 | B13: 伊賀 | C13: ANS-502 | D13: テレビ用手もとスピーカー | G13: 6 | H13: 2364 | I13: =VLOOKUP(C13,'202310-202403出荷数total2403220951'!B:F,5,0) -> 1052 | J13: =VLOOKUP(C13,'出荷数2307～2406total241008110618'!B:F,5,0) -> 1711 | K13: =VLOOKUP(C13,'出荷数2407-2506total250730101950'!B:F,5,0) -> 1026 | L13: =VLOOKUP(C:C,total251219111800!B:F,5,0) -> 587 | N13: =L13 -> 587 | O13: 3558 | P13: 0 | Q13: 0 | R13: 0 | S13: 0 | T13: 0 | U13: 3558 | V13: 2971 | W13: 0.16498033
A14: 10 | B14: 伊賀 | C14: ASL-3308US | D14: ウォールセンサーライト 箱 | E14: うさぎ | F14: 0 | G14: 3 | H14: 363 | I14: =VLOOKUP(C14,'202310-202403出荷数total2403220951'!B:F,5,0) -> #N/A | J14: =VLOOKUP(C14,'出荷数2307～2406total241008110618'!B:F,5,0) -> 1 | K14: =VLOOKUP(C14,'出荷数2407-2506total250730101950'!B:F,5,0) -> 7 | L14: =VLOOKUP(C:C,total251219111800!B:F,5,0) -> #N/A | N14: 0 | O14: 744 | P14: 0 | Q14: 0 | R14: 0 | S14: 0 | T14: 0 | U14: 744 | V14: 744 | W14: 0
A15: 11 | B15: 伊賀 | C15: ASL-3308CSK | D15: ウォールセンサーライト ブリスター | E15: しかく | F15: 23 | G15: 4 | H15: 0 | I15: =VLOOKUP(C15,'202310-202403出荷数total2403220951'!B:F,5,0) -> 1 | J15: =VLOOKUP(C15,'出荷数2307～2406total241008110618'!B:F,5,0) -> 705 | K15: =VLOOKUP(C15,'出荷数2407-2506total250730101950'!B:F,5,0) -> 1 | L15: =VLOOKUP(C:C,total251219111800!B:F,5,0) -> 1 | N15: =L15 -> 1 | O15: 0 | P15: 0 | Q15: 0 | R15: 0 | S15: 0 | T15: 0 | U15: 0 | V15: -1 | W15: #DIV/0!
A16: 12 | B16: 伊賀 | C16: ASL-3308CUS | D16: ウォールセンサーライト ブリスター | E16: うさぎ | F16: 35 | G16: 26 | H16: 5 | I16: =VLOOKUP(C16,'202310-202403出荷数total2403220951'!B:F,5,0) -> 3 | J16: =VLOOKUP(C16,'出荷数2307～2406total241008110618'!B:F,5,0) -> 6 | K16: =VLOOKUP(C16,'出荷数2407-2506total250730101950'!B:F,5,0) -> 3 | L16: =VLOOKUP(C:C,total251219111800!B:F,5,0) -> 142 | N16: =L16 -> 142 | O16: 4414 | P16: 0 | Q16: 0 | R16: 0 | S16: 0 | T16: 0 | U16: 4414 | V16: 4272 | W16: 0.032170367
A17: 13 | B17: 伊賀 | C17: AKM-3205PK | D17: 首ふり毛だまクリーナー | E17: ピンク | F17: 33 | G17: 24 | H17: 2990 | I17: =VLOOKUP(C17,'202310-202403出荷数total2403220951'!B:F,5,0) -> 66 | J17: =VLOOKUP(C17,'出荷数2307～2406total241008110618'!B:F,5,0) -> 189 | K17: =VLOOKUP(C17,'出荷数2407-2506total250730101950'!B:F,5,0) -> 97 | L17: =VLOOKUP(C:C,total251219111800!B:F,5,0) -> 77 | N17: =L17 -> 77 | O17: 2106 | P17: 0 | Q17: 0 | R17: 0 | S17: 0 | T17: 0 | U17: 2106 | V17: 2029 | W17: 0.036562203
A18: 14 | B18: 伊賀 | C18: ASN-4302 | D18: マグネット付ＬＥＤ信号灯 | F18: 149 | G18: 62 | H18: 132 | I18: =VLOOKUP(C18,'202310-202403出荷数total2403220951'!B:F,5,0) -> 245 | J18: =VLOOKUP(C18,'出荷数2307～2406total241008110618'!B:F,5,0) -> 322 | K18: =VLOOKUP(C18,'出荷数2407-2506total250730101950'!B:F,5,0) -> 206 | L18: =VLOOKUP(C:C,total251219111800!B:F,5,0) -> 17 | N18: =L18 -> 17 | O18: 2258 | P18: 0 | Q18: 0 | R18: 0 | S18: 0 | T18: 0 | U18: 2258 | V18: 2241 | W18: 0.0075287865 | X18: 売り切り廃盤予定
A19: 15 | B19: 伊賀 | C19: AIC-01IV | D19: ｷｽﾞつきにくいｲｽ脚ｶﾊﾞｰ | E19: IV | F19: 228 | G19: 270 | H19: 231 | I19: =VLOOKUP(C19,'202310-202403出荷数total2403220951'!B:F,5,0) -> 121 | J19: =VLOOKUP(C19,'出荷数2307～2406total241008110618'!B:F,5,0) -> 177 | K19: =VLOOKUP(C19,'出荷数2407-2506total250730101950'!B:F,5,0) -> 110 | L19: =VLOOKUP(C:C,total251219111800!B:F,5,0) -> 53 | N19: =L19 -> 53 | O19: 8060 | P19: 0 | Q19: 0 | R19: 0 | S19: 0 | T19: 0 | U19: 8060 | V19: 8007 | W19: 0.0065756824
A20: 16 | B20: 伊賀 | C20: ANS-603 | D20: お経の流れるスピーカーⅡ | G20: 128 | H20: 470 | I20: =VLOOKUP(C20,'202310-202403出荷数total2403220951'!B:F,5,0) -> 149 | J20: =VLOOKUP(C20,'出荷数2307～2406total241008110618'!B:F,5,0) -> 418 | K20: =VLOOKUP(C20,'出荷数2407-2506total250730101950'!B:F,5,0) -> 818 | L20: =VLOOKUP(C:C,total251219111800!B:F,5,0) -> 491 | N20: =L20 -> 491 | O20: 614 | P20: 130 | Q20: 0 | R20: 0 | S20: 280 | T20: -150 | U20: 334 | V20: -157 | W20: 0.65994624 | X20: トップ確保3月末まで確保
A21: 17 | B21: 伊賀 | C21: APY-105 | D21: 迷惑電話お断りピンポン | F21: 543 | G21: 321 | H21: 270 | I21: =VLOOKUP(C21,'202310-202403出荷数total2403220951'!B:F,5,0) -> 73 | J21: =VLOOKUP(C21,'出荷数2307～2406total241008110618'!B:F,5,0) -> 181 | K21: =VLOOKUP(C21,'出荷数2407-2506total250730101950'!B:F,5,0) -> 277 | L21: =VLOOKUP(C:C,total251219111800!B:F,5,0) -> 141 | N21: =L21 -> 141 | O21: 3326 | P21: 370 | Q21: 0 | R21: 0 | S21: 370 | T21: 0 | U21: 2956 | V21: 2815 | W21: 0.038149351
A22: 18 | B22: 伊賀 | C22: APL-3207S | D22: LEDのインテリア常備灯 | F22: 904 | G22: 638 | H22: 81 | I22: =VLOOKUP(C22,'202310-202403出荷数total2403220951'!B:F,5,0) -> 2 | J22: =VLOOKUP(C22,'出荷数2307～2406total241008110618'!B:F,5,0) -> 904 | K22: =VLOOKUP(C22,'出荷数2407-2506total250730101950'!B:F,5,0) -> 25 | L22: =VLOOKUP(C:C,total251219111800!B:F,5,0) -> 2 | N22: =L22 -> 2 | O22: 6860 | P22: 0 | Q22: 0 | R22: 0 | S22: 0 | T22: 0 | U22: 6860 | V22: 6858 | W22: 0.00029154519
A23: 19 | B23: 伊賀 | C23: ALA-4308BK-D | D23: ひっぱり点灯ライト 電球色ＬＥＤ | F23: 1137 | G23: 270 | H23: 272 | I23: =VLOOKUP(C23,'202310-202403出荷数total2403220951'!B:F,5,0) -> 153 | J23: =VLOOKUP(C23,'出荷数2307～2406total241008110618'!B:F,5,0) -> 657 | K23: =VLOOKUP(C23,'出荷数2407-2506total250730101950'!B:F,5,0) -> 101 | L23: =VLOOKUP(C:C,total251219111800!B:F,5,0) -> 88 | N23: =L23 -> 88 | O23: 1782 | P23: 0 | Q23: 0 | R23: 0 | S23: 0 | T23: 0 | U23: 1782 | V23: 1694 | W23: 0.049382716
A24: 20 | B24: 伊賀 | C24: ACA-101 | D24: ＬＥＤ帽子ライト | F24: 787 | G24: 450 | H24: 417 | I24: =VLOOKUP(C24,'202310-202403出荷数total2403220951'!B:F,5,0) -> 450 | J24: =VLOOKUP(C24,'出荷数2307～2406total241008110618'!B:F,5,0) -> 550 | K24: =VLOOKUP(C24,'出荷数2407-2506total250730101950'!B:F,5,0) -> 160 | L24: =VLOOKUP(C:C,total251219111800!B:F,5,0) -> 89 | N24: =L24 -> 89 | O24: 3706 | P24: 0 | Q24: 0 | R24: 0 | S24: 0 | T24: 0 | U24: 3706 | V24: 3617 | W24: 0.024015111
A25: 21 | B25: 伊賀 | C25: ASL-3308NE | D25: ウォールセンサーライト 箱 | E25: ねこ | F25: 13 | G25: 4 | H25: 8 | I25: =VLOOKUP(C25,'202310-202403出荷数total2403220951'!B:F,5,0) -> 1 | J25: =VLOOKUP(C25,'出荷数2307～2406total241008110618'!B:F,5,0) -> 4 | K25: =VLOOKUP(C25,'出荷数2407-2506total250730101950'!B:F,5,0) -> 6 | L25: =VLOOKUP(C:C,total251219111800!B:F,5,0) -> #N/A | N25: 0 | O25: 24 | P25: 0 | Q25: 0 | R25: 0 | S25: 0 | T25: 0 | U25: 24 | V25: 24 | W25: 0
A26: 22 | B26: 伊賀 | C26: AKD-20 | D26: アニマルシリコンバンド | F26: 1809 | G26: 790 | H26: 1042 | I26: =VLOOKUP(C26,'202310-202403出荷数total2403220951'!B:F,5,0) -> 164 | J26: =VLOOKUP(C26,'出荷数2307～2406total241008110618'!B:F,5,0) -> 312 | K26: =VLOOKUP(C26,'出荷数2407-2506total250730101950'!B:F,5,0) -> 454 | L26: =VLOOKUP(C:C,total251219111800!B:F,5,0) -> 168 | N26: =L26 -> 168 | O26: 5703 | P26: 300 | Q26: 0 | R26: 0 | S26: 300 | T26: 0 | U26: 5403 | V26: 5235 | W26: 0.027986007
A27: 23 | B27: 伊賀 | C27: ARA-4301 | D27: スマートフォンが使えるラジオライト | F27: 549 | G27: 303 | H27: 236 | I27: =VLOOKUP(C27,'202310-202403出荷数total2403220951'!B:F,5,0) -> 241 | J27: =VLOOKUP(C27,'出荷数2307～2406total241008110618'!B:F,5,0) -> 358 | K27: =VLOOKUP(C27,'出荷数2407-2506total250730101950'!B:F,5,0) -> 392 | L27: =VLOOKUP(C:C,total251219111800!B:F,5,0) -> 29 | N27: =L27 -> 29 | O27: 1917 | P27: 0 | Q27: 0 | R27: 0 | S27: 0 | T27: 0 | U27: 1917 | V27: 1888 | W27: 0.015127804
A28: 24 | B28: 伊賀 | C28: ASK-11BOR | D28: 巻きつく安全反射バンド(OR) | E28: オレンジ | F28: 1160 | G28: 148 | H28: 651 | I28: =VLOOKUP(C28,'202310-202403出荷数total2403220951'!B:F,5,0) -> 60 | J28: =VLOOKUP(C28,'出荷数2307～2406total241008110618'!B:F,5,0) -> 125 | K28: =VLOOKUP(C28,'出荷数2407-2506total250730101950'!B:F,5,0) -> 265 | L28: =VLOOKUP(C:C,total251219111800!B:F,5,0) -> 38 | M28: 500 | N28: 500 | O28: 2310 | P28: 0 | Q28: 0 | R28: 0 | S28: 0 | T28: 0 | U28: 2310 | V28: 1810 | W28: 0.21645022
A29: 25 | B29: 伊賀 | C29: ASK-10YE | D29: 光るホイール反射シール | E29: イエロー | F29: 935 | G29: 77 | H29: 731 | I29: =VLOOKUP(C29,'202310-202403出荷数total2403220951'!B:F,5,0) -> 163 | J29: =VLOOKUP(C29,'出荷数2307～2406total241008110618'!B:F,5,0) -> 235 | K29: =VLOOKUP(C29,'出荷数2407-2506total250730101950'!B:F,5,0) -> 20 | L29: =VLOOKUP(C:C,total251219111800!B:F,5,0) -> 2 | N29: =L29 -> 2 | O29: 5 | P29: 0 | Q29: 0 | R29: 0 | S29: 0 | T29: 0 | U29: 5 | V29: 3 | W29: 0.4
A30: 26 | B30: 伊賀 | C30: ARO-530GD | D30: 自動消灯安心のろうそく | E30: GD | F30: 224 | G30: 198 | H30: 230 | I30: =VLOOKUP(C30,'202310-202403出荷数total2403220951'!B:F,5,0) -> 91 | J30: =VLOOKUP(C30,'出荷数2307～2406total241008110618'!B:F,5,0) -> 168 | K30: =VLOOKUP(C30,'出荷数2407-2506total250730101950'!B:F,5,0) -> 52 | L30: =VLOOKUP(C:C,total251219111800!B:F,5,0) -> 28 | N30: =L30 -> 28 | O30: 920 | P30: 0 | Q30: 0 | R30: 0 | S30: 0 | T30: 0 | U30: 920 | V30: 892 | W30: 0.030434783
A31: 27 | B31: 伊賀 | C31: ALA-4308MO-W | D31: ひっぱり点灯ライト 木目 | E31: 木目 | F31: 714 | G31: 368 | H31: 496 | I31: =VLOOKUP(C31,'202310-202403出荷数total2403220951'!B:F,5,0) -> 150 | J31: =VLOOKUP(C31,'出荷数2307～2406total241008110618'!B:F,5,0) -> 247 | K31: =VLOOKUP(C31,'出荷数2407-2506total250730101950'!B:F,5,0) -> 43 | L31: =VLOOKUP(C:C,total251219111800!B:F,5,0) -> 29 | N31: =L31 -> 29 | O31: 1947 | P31: 0 | Q31: 0 | R31: 0 | S31: 0 | T31: 0 | U31: 1947 | V31: 1918 | W31: 0.01489471
A32: 28 | B32: 伊賀 | C32: AIC-06IV | D32: ｽﾞﾚにくいｲｽ脚ｶﾊﾞｰ 2脚用 | E32: IV | F32: 1116 | G32: 928 | H32: 1098 | I32: =VLOOKUP(C32,'202310-202403出荷数total2403220951'!B:F,5,0) -> 427 | J32: =VLOOKUP(C32,'出荷数2307～2406total241008110618'!B:F,5,0) -> 1008 | K32: =VLOOKUP(C32,'出荷数2407-2506total250730101950'!B:F,5,0) -> 854 | L32: =VLOOKUP(C:C,total251219111800!B:F,5,0) -> 345 | N32: =L32 -> 345 | O32: 3124 | P32: 0 | Q32: 0 | R32: 0 | S32: 0 | T32: 0 | U32: 3124 | V32: 2779 | W32: 0.11043534 | X32: 88％発注点よりﾏｲﾅｽ 345→41
A33: 29 | B33: 伊賀 | C33: ANS-701AD | D33: ＡＣアダプター701用 | F33: 120 | G33: 98 | H33: 141 | I33: =VLOOKUP(C33,'202310-202403出荷数total2403220951'!B:F,5,0) -> 41 | J33: =VLOOKUP(C33,'出荷数2307～2406total241008110618'!B:F,5,0) -> 89 | K33: =VLOOKUP(C33,'出荷数2407-2506total250730101950'!B:F,5,0) -> 92 | L33: =VLOOKUP(C:C,total251219111800!B:F,5,0) -> 49 | N33: =L33 -> 49 | O33: 319 | P33: 0 | Q33: 0 | R33: 0 | S33: 0 | T33: 0 | U33: 319 | V33: 270 | W33: 0.15360502
A34: 30 | B34: 伊賀 | C34: ANS-702 | D34: 大きな手もとスピーカー | F34: 1030 | G34: 390 | H34: 221 | I34: =VLOOKUP(C34,'202310-202403出荷数total2403220951'!B:F,5,0) -> 53 | J34: =VLOOKUP(C34,'出荷数2307～2406total241008110618'!B:F,5,0) -> 103 | K34: =VLOOKUP(C34,'出荷数2407-2506total250730101950'!B:F,5,0) -> 224 | L34: =VLOOKUP(C:C,total251219111800!B:F,5,0) -> 45 | N34: =L34 -> 45 | O34: 2080 | P34: 0 | Q34: 0 | R34: 0 | S34: 0 | T34: 0 | U34: 2080 | V34: 2035 | W34: 0.021634615
A35: 31 | B35: 伊賀 | C35: AKN-15 | D35: ハローキティ コンセントカバー | F35: 1322 | G35: 1075 | H35: 946 | I35: =VLOOKUP(C35,'202310-202403出荷数total2403220951'!B:F,5,0) -> 348 | J35: =VLOOKUP(C35,'出荷数2307～2406total241008110618'!B:F,5,0) -> 766 | K35: =VLOOKUP(C35,'出荷数2407-2506total250730101950'!B:F,5,0) -> 1074 | L35: =VLOOKUP(C:C,total251219111800!B:F,5,0) -> 327 | N35: =L35 -> 327 | O35: 3568 | P35: 0 | Q35: 0 | R35: 0 | S35: 0 | T35: 0 | U35: 3568 | V35: 3241 | W35: 0.091647982
A36: 32 | B36: 伊賀 | C36: ACA-3101 | D36: ＬＥＤアルミヘッドランプ | F36: 1781 | G36: 1472 | H36: 1360 | I36: =VLOOKUP(C36,'202310-202403出荷数total2403220951'!B:F,5,0) -> 3651 | J36: =VLOOKUP(C36,'出荷数2307～2406total241008110618'!B:F,5,0) -> 4452 | K36: =VLOOKUP(C36,'出荷数2407-2506total250730101950'!B:F,5,0) -> 4054 | L36: =VLOOKUP(C:C,total251219111800!B:F,5,0) -> 524 | N36: =L36 -> 524 | O36: 12996 | P36: 0 | Q36: 100 | R36: 0 | S36: 0 | T36: 0 | U36: 13096 | V36: 12572 | W36: 0.040320098
A37: 33 | B37: 伊賀 | C37: ASK-06SI | D37: はめるだけ光る 足腕バンド | E37: シルバー | F37: 1210 | G37: 214 | H37: 13 | I37: =VLOOKUP(C37,'202310-202403出荷数total2403220951'!B:F,5,0) -> 75 | J37: =VLOOKUP(C37,'出荷数2307～2406total241008110618'!B:F,5,0) -> 79 | K37: =VLOOKUP(C37,'出荷数2407-2506total250730101950'!B:F,5,0) -> 1 | L37: =VLOOKUP(C:C,total251219111800!B:F,5,0) -> 3 | N37: =L37 -> 3 | O37: 880 | P37: 0 | Q37: 0 | R37: 0 | S37: 0 | T37: 0 | U37: 880 | V37: 877 | W37: 0.0034090909
A38: 34 | B38: 伊賀 | C38: ASL-3308CNE | D38: ウォールセンサーライト ブリスター | E38: ねこ | F38: 271 | G38: 200 | H38: 124 | I38: =VLOOKUP(C38,'202310-202403出荷数total2403220951'!B:F,5,0) -> 63 | J38: =VLOOKUP(C38,'出荷数2307～2406total241008110618'!B:F,5,0) -> 93 | K38: =VLOOKUP(C38,'出荷数2407-2506total250730101950'!B:F,5,0) -> 14 | L38: =VLOOKUP(C:C,total251219111800!B:F,5,0) -> 140 | N38: =L38 -> 140 | O38: 797 | P38: 0 | Q38: 0 | R38: 0 | S38: 0 | T38: 0 | U38: 797 | V38: 657 | W38: 0.17565872
A39: 35 | B39: 伊賀 | C39: ASL-33082 | D39: ウォールセンサーライト（ショップチャンネル専用） | G39: 9 | H39: 1109 | I39: =VLOOKUP(C39,'202310-202403出荷数total2403220951'!B:F,5,0) -> #N/A | J39: =VLOOKUP(C39,'出荷数2307～2406total241008110618'!B:F,5,0) -> #N/A | K39: =VLOOKUP(C39,'出荷数2407-2506total250730101950'!B:F,5,0) -> #N/A | L39: =VLOOKUP(C:C,total251219111800!B:F,5,0) -> #N/A | M39: 470 | N39: 470 | O39: 106 | P39: 0 | Q39: 0 | R39: 0 | S39: 0 | T39: 0 | U39: 106 | V39: -364 | W39: 4.4339623
A40: 36 | B40: 伊賀 | C40: ADR-3401 | D40: 電動角質リムーバー | F40: 19 | G40: 1283 | H40: 7 | I40: =VLOOKUP(C40,'202310-202403出荷数total2403220951'!B:F,5,0) -> 223 | J40: =VLOOKUP(C40,'出荷数2307～2406total241008110618'!B:F,5,0) -> 598 | K40: =VLOOKUP(C40,'出荷数2407-2506total250730101950'!B:F,5,0) -> 73 | L40: =VLOOKUP(C:C,total251219111800!B:F,5,0) -> 5 | N40: =L40 -> 5 | O40: 4160 | P40: 0 | Q40: 0 | R40: 0 | S40: 0 | T40: 0 | U40: 4160 | V40: 4155 | W40: 0.0012019231
...

Sheet 80123
B1: 商品センター | C1: 品番 | D1: 商品区分 | E1: カラー | F1: 72期 | G1: 73期 | H1: 74期(1期) | I1: 2023/10/1～2024/3/21（6か月） | J1: 75期(2期) | K1: 76期（３期 ） | L1: 77期（4期 7/1-12/18） | N1: 発注点 5ヶ月分なのでそのまま | O1: 在庫数 ロジザード | Q1: 入荷予定 ロジザード | S1: 確保数 弥生(在庫確保) | T1: 確保数チェック 0じゃなかったらロジザード修正 | U1: 有効数量 フリー在庫の数 | V1: 発注検討フラグ マイナスの場合発注検討 | W1: 在庫回転率 | X1: 前回決定事項（1/16） | Y1: 決定事項 | AE1: 前回決定事項（/） | AG1: 決定事項
A2: 1 | B2: 伊賀 | C2: APL-4312SBL | D2: ミニホイッスル付LEDアルミライトⅡ | H2: 192 | I2: =VLOOKUP(C2,'202310-202403出荷数total2403220951'!B:F,5,0) -> 71 | J2: =VLOOKUP(C2,'出荷数2307～2406total241008110618'!B:F,5,0) -> 281 | K2: =VLOOKUP(C2,'出荷数2407-2506total250730101950'!B:F,5,0) -> 902 | L2: =VLOOKUP(C:C,total251219111800!B:F,5,0) -> 386 | N2: =L2 -> 386 | O2: 427 | P2: 640 | Q2: 0 | R2: 0 | S2: 540 | T2: 100 | U2: -113 | V2: -499 | W2: 0.36176195
A3: 2 | B3: 伊賀 | C3: APL-4312SPK | D3: ミニホイッスル付LEDアルミライトⅡ | H3: 2161 | I3: =VLOOKUP(C3,'202310-202403出荷数total2403220951'!B:F,5,0) -> 1018 | J3: =VLOOKUP(C3,'出荷数2307～2406total241008110618'!B:F,5,0) -> 1930 | K3: =VLOOKUP(C3,'出荷数2407-2506total250730101950'!B:F,5,0) -> 3388 | L3: =VLOOKUP(C:C,total251219111800!B:F,5,0) -> 903 | N3: =L3 -> 903 | O3: 1882 | P3: 1880 | Q3: 0 | R3: 0 | S3: 1790 | T3: 90 | U3: 92 | V3: -811 | W3: 0.2400319
A4: 86 | B4: 伊賀 | C4: ABO-08BL | D4: ミニホイッスル | E4: ブルー | F4: 527 | G4: 2107 | H4: 796 | I4: =VLOOKUP(C4,'202310-202403出荷数total2403220951'!B:F,5,0) -> 1409 | J4: =VLOOKUP(C4,'出荷数2307～2406total241008110618'!B:F,5,0) -> 1708 | K4: =VLOOKUP(C4,'出荷数2407-2506total250730101950'!B:F,5,0) -> 1865 | L4: =VLOOKUP(C:C,total251219111800!B:F,5,0) -> 474 | M4: 1000 | N4: 1000 | O4: 6766 | P4: 0 | Q4: 0 | R4: 0 | S4: 0 | T4: 0 | U4: 6766 | V4: 5766 | W4: 0.14779781
A5: 107 | B5: 伊賀 | C5: ABO-08PK | D5: ミニホイッスル | E5: ピンク | F5: 3939 | G5: 5966 | H5: 5009 | I5: =VLOOKUP(C5,'202310-202403出荷数total2403220951'!B:F,5,0) -> 6490 | J5: =VLOOKUP(C5,'出荷数2307～2406total241008110618'!B:F,5,0) -> 17931 | K5: =VLOOKUP(C5,'出荷数2407-2506total250730101950'!B:F,5,0) -> 28387 | L5: =VLOOKUP(C:C,total251219111800!B:F,5,0) -> 4495 | N5: =L5 -> 4495 | O5: 28550 | P5: 24430 | Q5: 800 | R5: 0 | S5: 24430 | T5: 0 | U5: 4920 | V5: 425 | W5: 0.084843337
A6: 109 | B6: 伊賀 | C6: APL-4302S | D6: ＬＥＤミニアルミライト | F6: 1094 | G6: 3475 | H6: 834 | I6: =VLOOKUP(C6,'202310-202403出荷数total2403220951'!B:F,5,0) -> 444 | J6: =VLOOKUP(C6,'出荷数2307～2406total241008110618'!B:F,5,0) -> 789 | K6: =VLOOKUP(C6,'出荷数2407-2506total250730101950'!B:F,5,0) -> 232 | L6: =VLOOKUP(C:C,total251219111800!B:F,5,0) -> 177 | N6: =L6 -> 177 | O6: 3754 | P6: 0 | Q6: 300 | R6: 0 | S6: 0 | T6: 0 | U6: 4054 | V6: 3877 | W6: 0.047149707
A7: 3 | B7: 伊賀 | C7: ASL-3308SK | D7: ウォールセンサーライト 箱 | E7: しかく | F7: 1 | G7: 0 | H7: 4 | I7: =VLOOKUP(C7,'202310-202403出荷数total2403220951'!B:F,5,0) -> #N/A | J7: =VLOOKUP(C7,'出荷数2307～2406total241008110618'!B:F,5,0) -> #N/A | K7: =VLOOKUP(C7,'出荷数2407-2506total250730101950'!B:F,5,0) -> #N/A | L7: =VLOOKUP(C:C,total251219111800!B:F,5,0) -> #N/A | N7: 0 | O7: 1 | P7: 0 | Q7: 0 | R7: 0 | S7: 0 | T7: 0 | U7: 1 | V7: 1 | W7: 0
A8: 4 | B8: 伊賀 | C8: AHL-3201RD | D8: LEDハンディライト | H8: 2048 | I8: =VLOOKUP(C8,'202310-202403出荷数total2403220951'!B:F,5,0) -> 2098 | J8: =VLOOKUP(C8,'出荷数2307～2406total241008110618'!B:F,5,0) -> 3644 | K8: =VLOOKUP(C8,'出荷数2407-2506total250730101950'!B:F,5,0) -> 2910 | L8: =VLOOKUP(C:C,total251219111800!B:F,5,0) -> 2559 | N8: =L8 -> 2559 | O8: 3061 | P8: 0 | Q8: 0 | R8: 0 | S8: 0 | T8: 0 | U8: 3061 | V8: 502 | W8: 0.83600131
A9: 5 | B9: 伊賀 | C9: AHL-3201WH | D9: LEDハンディライト | H9: 116 | I9: =VLOOKUP(C9,'202310-202403出荷数total2403220951'!B:F,5,0) -> 220 | J9: =VLOOKUP(C9,'出荷数2307～2406total241008110618'!B:F,5,0) -> 378 | K9: =VLOOKUP(C9,'出荷数2407-2506total250730101950'!B:F,5,0) -> 2016 | L9: =VLOOKUP(C:C,total251219111800!B:F,5,0) -> 281 | M9: 1000 | N9: 1000 | O9: 5183 | P9: 0 | Q9: 0 | R9: 0 | S9: 0 | T9: 0 | U9: 5183 | V9: 4183 | W9: 0.19293845
A10: 6 | B10: 伊賀 | C10: AHL-1400 | D10: LED強力ライト | H10: 15126 | I10: =VLOOKUP(C10,'202310-202403出荷数total2403220951'!B:F,5,0) -> 9163 | J10: =VLOOKUP(C10,'出荷数2307～2406total241008110618'!B:F,5,0) -> 19757 | K10: =VLOOKUP(C10,'出荷数2407-2506total250730101950'!B:F,5,0) -> 20812 | L10: =VLOOKUP(C:C,total251219111800!B:F,5,0) -> 4356 | N10: =L10 -> 4356 | O10: 1550 | P10: 13515 | Q10: 0 | R10: 0 | S10: 14405 | T10: -890 | U10: -12855 | V10: -17211 | W10: 0.28914703
A11: 7 | B11: 伊賀 | C11: AHL-1400T | D11: LED強力ライト(トップ) | H11: 2084 | I11: =VLOOKUP(C11,'202310-202403出荷数total2403220951'!B:F,5,0) -> 1160 | J11: =VLOOKUP(C11,'出荷数2307～2406total241008110618'!B:F,5,0) -> 1821 | K11: =VLOOKUP(C11,'出荷数2407-2506total250730101950'!B:F,5,0) -> 1120 | L11: =VLOOKUP(C:C,total251219111800!B:F,5,0) -> 160 | N11: =L11 -> 160 | O11: 2 | P11: 0 | Q11: 0 | R11: 0 | S11: 0 | T11: 0 | U11: 2 | V11: -158 | W11: 80
A12: 8 | B12: 伊賀 | C12: ASL-3308KU | D12: ウォールセンサーライト 箱 | E12: くも | F12: 193 | G12: 1 | H12: 100 | I12: =VLOOKUP(C12,'202310-202403出荷数total2403220951'!B:F,5,0) -> 43 | J12: =VLOOKUP(C12,'出荷数2307～2406total241008110618'!B:F,5,0) -> 51 | K12: =VLOOKUP(C12,'出荷数2407-2506total250730101950'!B:F,5,0) -> 12 | L12: =VLOOKUP(C:C,total251219111800!B:F,5,0) -> 3 | N12: =L12 -> 3 | O12: 999 | P12: 0 | Q12: 0 | R12: 0 | S12: 0 | T12: 0 | U12: 999 | V12: 996 | W12: 0.003003003
A13: 9 | B13: 伊賀 | C13: ANS-502 | D13: テレビ用手もとスピーカー | G13: 6 | H13: 2364 | I13: =VLOOKUP(C13,'202310-202403出荷数total2403220951'!B:F,5,0) -> 1052 | J13: =VLOOKUP(C13,'出荷数2307～2406total241008110618'!B:F,5,0) -> 1711 | K13: =VLOOKUP(C13,'出荷数2407-2506total250730101950'!B:F,5,0) -> 1026 | L13: =VLOOKUP(C:C,total251219111800!B:F,5,0) -> 587 | N13: =L13 -> 587 | O13: 3548 | P13: 0 | Q13: 0 | R13: 0 | S13: 0 | T13: 0 | U13: 3548 | V13: 2961 | W13: 0.16544532
A14: 10 | B14: 伊賀 | C14: ASL-3308US | D14: ウォールセンサーライト 箱 | E14: うさぎ | F14: 0 | G14: 3 | H14: 363 | I14: =VLOOKUP(C14,'202310-202403出荷数total2403220951'!B:F,5,0) -> #N/A | J14: =VLOOKUP(C14,'出荷数2307～2406total241008110618'!B:F,5,0) -> 1 | K14: =VLOOKUP(C14,'出荷数2407-2506total250730101950'!B:F,5,0) -> 7 | L14: =VLOOKUP(C:C,total251219111800!B:F,5,0) -> #N/A | N14: 0 | O14: 744 | P14: 0 | Q14: 0 | R14: 0 | S14: 0 | T14: 0 | U14: 744 | V14: 744 | W14: 0
A15: 11 | B15: 伊賀 | C15: ASL-3308CSK | D15: ウォールセンサーライト ブリスター | E15: しかく | F15: 23 | G15: 4 | H15: 0 | I15: =VLOOKUP(C15,'202310-202403出荷数total2403220951'!B:F,5,0) -> 1 | J15: =VLOOKUP(C15,'出荷数2307～2406total241008110618'!B:F,5,0) -> 705 | K15: =VLOOKUP(C15,'出荷数2407-2506total250730101950'!B:F,5,0) -> 1 | L15: =VLOOKUP(C:C,total251219111800!B:F,5,0) -> 1 | N15: =L15 -> 1 | O15: 0 | P15: 0 | Q15: 0 | R15: 0 | S15: 0 | T15: 0 | U15: 0 | V15: -1 | W15: #DIV/0!
A16: 12 | B16: 伊賀 | C16: ASL-3308CUS | D16: ウォールセンサーライト ブリスター | E16: うさぎ | F16: 35 | G16: 26 | H16: 5 | I16: =VLOOKUP(C16,'202310-202403出荷数total2403220951'!B:F,5,0) -> 3 | J16: =VLOOKUP(C16,'出荷数2307～2406total241008110618'!B:F,5,0) -> 6 | K16: =VLOOKUP(C16,'出荷数2407-2506total250730101950'!B:F,5,0) -> 3 | L16: =VLOOKUP(C:C,total251219111800!B:F,5,0) -> 142 | N16: =L16 -> 142 | O16: 4414 | P16: 0 | Q16: 0 | R16: 0 | S16: 0 | T16: 0 | U16: 4414 | V16: 4272 | W16: 0.032170367
A17: 13 | B17: 伊賀 | C17: AKM-3205PK | D17: 首ふり毛だまクリーナー | E17: ピンク | F17: 33 | G17: 24 | H17: 2990 | I17: =VLOOKUP(C17,'202310-202403出荷数total2403220951'!B:F,5,0) -> 66 | J17: =VLOOKUP(C17,'出荷数2307～2406total241008110618'!B:F,5,0) -> 189 | K17: =VLOOKUP(C17,'出荷数2407-2506total250730101950'!B:F,5,0) -> 97 | L17: =VLOOKUP(C:C,total251219111800!B:F,5,0) -> 77 | N17: =L17 -> 77 | O17: 2106 | P17: 0 | Q17: 0 | R17: 0 | S17: 0 | T17: 0 | U17: 2106 | V17: 2029 | W17: 0.036562203
A18: 14 | B18: 伊賀 | C18: ASN-4302 | D18: マグネット付ＬＥＤ信号灯 | F18: 149 | G18: 62 | H18: 132 | I18: =VLOOKUP(C18,'202310-202403出荷数total2403220951'!B:F,5,0) -> 245 | J18: =VLOOKUP(C18,'出荷数2307～2406total241008110618'!B:F,5,0) -> 322 | K18: =VLOOKUP(C18,'出荷数2407-2506total250730101950'!B:F,5,0) -> 206 | L18: =VLOOKUP(C:C,total251219111800!B:F,5,0) -> 17 | N18: =L18 -> 17 | O18: 2258 | P18: 0 | Q18: 0 | R18: 0 | S18: 0 | T18: 0 | U18: 2258 | V18: 2241 | W18: 0.0075287865 | X18: 売り切り廃盤予定
A19: 15 | B19: 伊賀 | C19: AIC-01IV | D19: ｷｽﾞつきにくいｲｽ脚ｶﾊﾞｰ | E19: IV | F19: 228 | G19: 270 | H19: 231 | I19: =VLOOKUP(C19,'202310-202403出荷数total2403220951'!B:F,5,0) -> 121 | J19: =VLOOKUP(C19,'出荷数2307～2406total241008110618'!B:F,5,0) -> 177 | K19: =VLOOKUP(C19,'出荷数2407-2506total250730101950'!B:F,5,0) -> 110 | L19: =VLOOKUP(C:C,total251219111800!B:F,5,0) -> 53 | N19: =L19 -> 53 | O19: 8059 | P19: 0 | Q19: 0 | R19: 0 | S19: 0 | T19: 0 | U19: 8059 | V19: 8006 | W19: 0.0065764983
A20: 16 | B20: 伊賀 | C20: ANS-603 | D20: お経の流れるスピーカーⅡ | G20: 128 | H20: 470 | I20: =VLOOKUP(C20,'202310-202403出荷数total2403220951'!B:F,5,0) -> 149 | J20: =VLOOKUP(C20,'出荷数2307～2406total241008110618'!B:F,5,0) -> 418 | K20: =VLOOKUP(C20,'出荷数2407-2506total250730101950'!B:F,5,0) -> 818 | L20: =VLOOKUP(C:C,total251219111800!B:F,5,0) -> 491 | N20: =L20 -> 491 | O20: 598 | P20: 130 | Q20: 0 | R20: 0 | S20: 130 | T20: 0 | U20: 468 | V20: -23 | W20: 0.67445055 | X20: トップ確保3月末まで確保
A21: 17 | B21: 伊賀 | C21: APY-105 | D21: 迷惑電話お断りピンポン | F21: 543 | G21: 321 | H21: 270 | I21: =VLOOKUP(C21,'202310-202403出荷数total2403220951'!B:F,5,0) -> 73 | J21: =VLOOKUP(C21,'出荷数2307～2406total241008110618'!B:F,5,0) -> 181 | K21: =VLOOKUP(C21,'出荷数2407-2506total250730101950'!B:F,5,0) -> 277 | L21: =VLOOKUP(C:C,total251219111800!B:F,5,0) -> 141 | N21: =L21 -> 141 | O21: 3311 | P21: 370 | Q21: 0 | R21: 0 | S21: 370 | T21: 0 | U21: 2941 | V21: 2800 | W21: 0.038304808
A22: 18 | B22: 伊賀 | C22: APL-3207S | D22: LEDのインテリア常備灯 | F22: 904 | G22: 638 | H22: 81 | I22: =VLOOKUP(C22,'202310-202403出荷数total2403220951'!B:F,5,0) -> 2 | J22: =VLOOKUP(C22,'出荷数2307～2406total241008110618'!B:F,5,0) -> 904 | K22: =VLOOKUP(C22,'出荷数2407-2506total250730101950'!B:F,5,0) -> 25 | L22: =VLOOKUP(C:C,total251219111800!B:F,5,0) -> 2 | N22: =L22 -> 2 | O22: 6860 | P22: 0 | Q22: 0 | R22: 0 | S22: 0 | T22: 0 | U22: 6860 | V22: 6858 | W22: 0.00029154519
A23: 19 | B23: 伊賀 | C23: ALA-4308BK-D | D23: ひっぱり点灯ライト 電球色ＬＥＤ | F23: 1137 | G23: 270 | H23: 272 | I23: =VLOOKUP(C23,'202310-202403出荷数total2403220951'!B:F,5,0) -> 153 | J23: =VLOOKUP(C23,'出荷数2307～2406total241008110618'!B:F,5,0) -> 657 | K23: =VLOOKUP(C23,'出荷数2407-2506total250730101950'!B:F,5,0) -> 101 | L23: =VLOOKUP(C:C,total251219111800!B:F,5,0) -> 88 | N23: =L23 -> 88 | O23: 1782 | P23: 0 | Q23: 0 | R23: 0 | S23: 0 | T23: 0 | U23: 1782 | V23: 1694 | W23: 0.049382716
A24: 20 | B24: 伊賀 | C24: ACA-101 | D24: ＬＥＤ帽子ライト | F24: 787 | G24: 450 | H24: 417 | I24: =VLOOKUP(C24,'202310-202403出荷数total2403220951'!B:F,5,0) -> 450 | J24: =VLOOKUP(C24,'出荷数2307～2406total241008110618'!B:F,5,0) -> 550 | K24: =VLOOKUP(C24,'出荷数2407-2506total250730101950'!B:F,5,0) -> 160 | L24: =VLOOKUP(C:C,total251219111800!B:F,5,0) -> 89 | N24: =L24 -> 89 | O24: 3704 | P24: 0 | Q24: 0 | R24: 0 | S24: 0 | T24: 0 | U24: 3704 | V24: 3615 | W24: 0.024028078
A25: 21 | B25: 伊賀 | C25: ASL-3308NE | D25: ウォールセンサーライト 箱 | E25: ねこ | F25: 13 | G25: 4 | H25: 8 | I25: =VLOOKUP(C25,'202310-202403出荷数total2403220951'!B:F,5,0) -> 1 | J25: =VLOOKUP(C25,'出荷数2307～2406total241008110618'!B:F,5,0) -> 4 | K25: =VLOOKUP(C25,'出荷数2407-2506total250730101950'!B:F,5,0) -> 6 | L25: =VLOOKUP(C:C,total251219111800!B:F,5,0) -> #N/A | N25: 0 | O25: 24 | P25: 0 | Q25: 0 | R25: 0 | S25: 0 | T25: 0 | U25: 24 | V25: 24 | W25: 0
A26: 22 | B26: 伊賀 | C26: AKD-20 | D26: アニマルシリコンバンド | F26: 1809 | G26: 790 | H26: 1042 | I26: =VLOOKUP(C26,'202310-202403出荷数total2403220951'!B:F,5,0) -> 164 | J26: =VLOOKUP(C26,'出荷数2307～2406total241008110618'!B:F,5,0) -> 312 | K26: =VLOOKUP(C26,'出荷数2407-2506total250730101950'!B:F,5,0) -> 454 | L26: =VLOOKUP(C:C,total251219111800!B:F,5,0) -> 168 | N26: =L26 -> 168 | O26: 5694 | P26: 300 | Q26: 0 | R26: 0 | S26: 300 | T26: 0 | U26: 5394 | V26: 5226 | W26: 0.028028028
A27: 23 | B27: 伊賀 | C27: ARA-4301 | D27: スマートフォンが使えるラジオライト | F27: 549 | G27: 303 | H27: 236 | I27: =VLOOKUP(C27,'202310-202403出荷数total2403220951'!B:F,5,0) -> 241 | J27: =VLOOKUP(C27,'出荷数2307～2406total241008110618'!B:F,5,0) -> 358 | K27: =VLOOKUP(C27,'出荷数2407-2506total250730101950'!B:F,5,0) -> 392 | L27: =VLOOKUP(C:C,total251219111800!B:F,5,0) -> 29 | N27: =L27 -> 29 | O27: 1917 | P27: 0 | Q27: 0 | R27: 0 | S27: 0 | T27: 0 | U27: 1917 | V27: 1888 | W27: 0.015127804
A28: 24 | B28: 伊賀 | C28: ASK-11BOR | D28: 巻きつく安全反射バンド(OR) | E28: オレンジ | F28: 1160 | G28: 148 | H28: 651 | I28: =VLOOKUP(C28,'202310-202403出荷数total2403220951'!B:F,5,0) -> 60 | J28: =VLOOKUP(C28,'出荷数2307～2406total241008110618'!B:F,5,0) -> 125 | K28: =VLOOKUP(C28,'出荷数2407-2506total250730101950'!B:F,5,0) -> 265 | L28: =VLOOKUP(C:C,total251219111800!B:F,5,0) -> 38 | M28: 500 | N28: 500 | O28: 2309 | P28: 0 | Q28: 0 | R28: 0 | S28: 0 | T28: 0 | U28: 2309 | V28: 1809 | W28: 0.21654396
A29: 25 | B29: 伊賀 | C29: ASK-10YE | D29: 光るホイール反射シール | E29: イエロー | F29: 935 | G29: 77 | H29: 731 | I29: =VLOOKUP(C29,'202310-202403出荷数total2403220951'!B:F,5,0) -> 163 | J29: =VLOOKUP(C29,'出荷数2307～2406total241008110618'!B:F,5,0) -> 235 | K29: =VLOOKUP(C29,'出荷数2407-2506total250730101950'!B:F,5,0) -> 20 | L29: =VLOOKUP(C:C,total251219111800!B:F,5,0) -> 2 | N29: =L29 -> 2 | O29: 5 | P29: 0 | Q29: 0 | R29: 0 | S29: 0 | T29: 0 | U29: 5 | V29: 3 | W29: 0.4
A30: 26 | B30: 伊賀 | C30: ARO-530GD | D30: 自動消灯安心のろうそく | E30: GD | F30: 224 | G30: 198 | H30: 230 | I30: =VLOOKUP(C30,'202310-202403出荷数total2403220951'!B:F,5,0) -> 91 | J30: =VLOOKUP(C30,'出荷数2307～2406total241008110618'!B:F,5,0) -> 168 | K30: =VLOOKUP(C30,'出荷数2407-2506total250730101950'!B:F,5,0) -> 52 | L30: =VLOOKUP(C:C,total251219111800!B:F,5,0) -> 28 | N30: =L30 -> 28 | O30: 920 | P30: 0 | Q30: 0 | R30: 0 | S30: 0 | T30: 0 | U30: 920 | V30: 892 | W30: 0.030434783
A31: 27 | B31: 伊賀 | C31: ALA-4308MO-W | D31: ひっぱり点灯ライト 木目 | E31: 木目 | F31: 714 | G31: 368 | H31: 496 | I31: =VLOOKUP(C31,'202310-202403出荷数total2403220951'!B:F,5,0) -> 150 | J31: =VLOOKUP(C31,'出荷数2307～2406total241008110618'!B:F,5,0) -> 247 | K31: =VLOOKUP(C31,'出荷数2407-2506total250730101950'!B:F,5,0) -> 43 | L31: =VLOOKUP(C:C,total251219111800!B:F,5,0) -> 29 | N31: =L31 -> 29 | O31: 1947 | P31: 0 | Q31: 0 | R31: 0 | S31: 0 | T31: 0 | U31: 1947 | V31: 1918 | W31: 0.01489471
A32: 28 | B32: 伊賀 | C32: AIC-06IV | D32: ｽﾞﾚにくいｲｽ脚ｶﾊﾞｰ 2脚用 | E32: IV | F32: 1116 | G32: 928 | H32: 1098 | I32: =VLOOKUP(C32,'202310-202403出荷数total2403220951'!B:F,5,0) -> 427 | J32: =VLOOKUP(C32,'出荷数2307～2406total241008110618'!B:F,5,0) -> 1008 | K32: =VLOOKUP(C32,'出荷数2407-2506total250730101950'!B:F,5,0) -> 854 | L32: =VLOOKUP(C:C,total251219111800!B:F,5,0) -> 345 | N32: =L32 -> 345 | O32: 3044 | P32: 0 | Q32: 0 | R32: 0 | S32: 0 | T32: 0 | U32: 3044 | V32: 2699 | W32: 0.11333771 | X32: 88％発注点よりﾏｲﾅｽ 345→41
A33: 29 | B33: 伊賀 | C33: ANS-701AD | D33: ＡＣアダプター701用 | F33: 120 | G33: 98 | H33: 141 | I33: =VLOOKUP(C33,'202310-202403出荷数total2403220951'!B:F,5,0) -> 41 | J33: =VLOOKUP(C33,'出荷数2307～2406total241008110618'!B:F,5,0) -> 89 | K33: =VLOOKUP(C33,'出荷数2407-2506total250730101950'!B:F,5,0) -> 92 | L33: =VLOOKUP(C:C,total251219111800!B:F,5,0) -> 49 | N33: =L33 -> 49 | O33: 317 | P33: 0 | Q33: 0 | R33: 0 | S33: 0 | T33: 0 | U33: 317 | V33: 268 | W33: 0.15457413
A34: 30 | B34: 伊賀 | C34: ANS-702 | D34: 大きな手もとスピーカー | F34: 1030 | G34: 390 | H34: 221 | I34: =VLOOKUP(C34,'202310-202403出荷数total2403220951'!B:F,5,0) -> 53 | J34: =VLOOKUP(C34,'出荷数2307～2406total241008110618'!B:F,5,0) -> 103 | K34: =VLOOKUP(C34,'出荷数2407-2506total250730101950'!B:F,5,0) -> 224 | L34: =VLOOKUP(C:C,total251219111800!B:F,5,0) -> 45 | N34: =L34 -> 45 | O34: 2079 | P34: 0 | Q34: 0 | R34: 0 | S34: 0 | T34: 0 | U34: 2079 | V34: 2034 | W34: 0.021645022
A35: 31 | B35: 伊賀 | C35: AKN-15 | D35: ハローキティ コンセントカバー | F35: 1322 | G35: 1075 | H35: 946 | I35: =VLOOKUP(C35,'202310-202403出荷数total2403220951'!B:F,5,0) -> 348 | J35: =VLOOKUP(C35,'出荷数2307～2406total241008110618'!B:F,5,0) -> 766 | K35: =VLOOKUP(C35,'出荷数2407-2506total250730101950'!B:F,5,0) -> 1074 | L35: =VLOOKUP(C:C,total251219111800!B:F,5,0) -> 327 | N35: =L35 -> 327 | O35: 3568 | P35: 0 | Q35: 0 | R35: 0 | S35: 0 | T35: 0 | U35: 3568 | V35: 3241 | W35: 0.091647982
A36: 32 | B36: 伊賀 | C36: ACA-3101 | D36: ＬＥＤアルミヘッドランプ | F36: 1781 | G36: 1472 | H36: 1360 | I36: =VLOOKUP(C36,'202310-202403出荷数total2403220951'!B:F,5,0) -> 3651 | J36: =VLOOKUP(C36,'出荷数2307～2406total241008110618'!B:F,5,0) -> 4452 | K36: =VLOOKUP(C36,'出荷数2407-2506total250730101950'!B:F,5,0) -> 4054 | L36: =VLOOKUP(C:C,total251219111800!B:F,5,0) -> 524 | N36: =L36 -> 524 | O36: 12994 | P36: 0 | Q36: 100 | R36: 0 | S36: 0 | T36: 0 | U36: 13094 | V36: 12570 | W36: 0.040326304
A37: 33 | B37: 伊賀 | C37: ASK-06SI | D37: はめるだけ光る 足腕バンド | E37: シルバー | F37: 1210 | G37: 214 | H37: 13 | I37: =VLOOKUP(C37,'202310-202403出荷数total2403220951'!B:F,5,0) -> 75 | J37: =VLOOKUP(C37,'出荷数2307～2406total241008110618'!B:F,5,0) -> 79 | K37: =VLOOKUP(C37,'出荷数2407-2506total250730101950'!B:F,5,0) -> 1 | L37: =VLOOKUP(C:C,total251219111800!B:F,5,0) -> 3 | N37: =L37 -> 3 | O37: 875 | P37: 0 | Q37: 0 | R37: 0 | S37: 0 | T37: 0 | U37: 875 | V37: 872 | W37: 0.0034285714
A38: 34 | B38: 伊賀 | C38: ASL-3308CNE | D38: ウォールセンサーライト ブリスター | E38: ねこ | F38: 271 | G38: 200 | H38: 124 | I38: =VLOOKUP(C38,'202310-202403出荷数total2403220951'!B:F,5,0) -> 63 | J38: =VLOOKUP(C38,'出荷数2307～2406total241008110618'!B:F,5,0) -> 93 | K38: =VLOOKUP(C38,'出荷数2407-2506total250730101950'!B:F,5,0) -> 14 | L38: =VLOOKUP(C:C,total251219111800!B:F,5,0) -> 140 | N38: =L38 -> 140 | O38: 797 | P38: 0 | Q38: 0 | R38: 0 | S38: 0 | T38: 0 | U38: 797 | V38: 657 | W38: 0.17565872
A39: 35 | B39: 伊賀 | C39: ASL-33082 | D39: ウォールセンサーライト（ショップチャンネル専用） | G39: 9 | H39: 1109 | I39: =VLOOKUP(C39,'202310-202403出荷数total2403220951'!B:F,5,0) -> #N/A | J39: =VLOOKUP(C39,'出荷数2307～2406total241008110618'!B:F,5,0) -> #N/A | K39: =VLOOKUP(C39,'出荷数2407-2506total250730101950'!B:F,5,0) -> #N/A | L39: =VLOOKUP(C:C,total251219111800!B:F,5,0) -> #N/A | M39: 470 | N39: 470 | O39: 106 | P39: 0 | Q39: 0 | R39: 0 | S39: 0 | T39: 0 | U39: 106 | V39: -364 | W39: 4.4339623
A40: 36 | B40: 伊賀 | C40: ADR-3401 | D40: 電動角質リムーバー | F40: 19 | G40: 1283 | H40: 7 | I40: =VLOOKUP(C40,'202310-202403出荷数total2403220951'!B:F,5,0) -> 223 | J40: =VLOOKUP(C40,'出荷数2307～2406total241008110618'!B:F,5,0) -> 598 | K40: =VLOOKUP(C40,'出荷数2407-2506total250730101950'!B:F,5,0) -> 73 | L40: =VLOOKUP(C:C,total251219111800!B:F,5,0) -> 5 | N40: =L40 -> 5 | O40: 4160 | P40: 0 | Q40: 0 | R40: 0 | S40: 0 | T40: 0 | U40: 4160 | V40: 4155 | W40: 0.0012019231
...

Sheet 80130
B1: 商品センター | C1: 品番 | D1: 商品区分 | E1: カラー | F1: 72期 | G1: 73期 | H1: 74期(1期) | I1: 2023/10/1～2024/3/21（6か月） | J1: 75期(2期) | K1: 76期（３期 ） | L1: 77期（4期 7/1-12/18） | N1: 発注点 5ヶ月分なのでそのまま | O1: 在庫数 ロジザード | Q1: 入荷予定 ロジザード | S1: 確保数 弥生(在庫確保) | T1: 確保数チェック 0じゃなかったらロジザード修正 | U1: 有効数量 フリー在庫の数 | V1: 発注検討フラグ マイナスの場合発注検討 | W1: 在庫回転率 | X1: 前回決定事項（1/23） | Y1: 決定事項 | AE1: 前回決定事項（/） | AG1: 決定事項
A2: 1 | B2: 伊賀 | C2: APL-4312SBL | D2: ミニホイッスル付LEDアルミライトⅡ | H2: 192 | I2: =VLOOKUP(C2,'202310-202403出荷数total2403220951'!B:F,5,0) -> 71 | J2: =VLOOKUP(C2,'出荷数2307～2406total241008110618'!B:F,5,0) -> 281 | K2: =VLOOKUP(C2,'出荷数2407-2506total250730101950'!B:F,5,0) -> 902 | L2: =VLOOKUP(C:C,total251219111800!B:F,5,0) -> 386 | N2: =L2 -> 386 | O2: 327 | P2: 700 | Q2: 0 | R2: 0 | S2: 540 | T2: 160 | U2: -213 | V2: -599 | W2: 0.375852
A3: 2 | B3: 伊賀 | C3: APL-4312SPK | D3: ミニホイッスル付LEDアルミライトⅡ | H3: 2161 | I3: =VLOOKUP(C3,'202310-202403出荷数total2403220951'!B:F,5,0) -> 1018 | J3: =VLOOKUP(C3,'出荷数2307～2406total241008110618'!B:F,5,0) -> 1930 | K3: =VLOOKUP(C3,'出荷数2407-2506total250730101950'!B:F,5,0) -> 3388 | L3: =VLOOKUP(C:C,total251219111800!B:F,5,0) -> 903 | N3: =L3 -> 903 | O3: 1782 | P3: 1290 | Q3: 0 | R3: 0 | S3: 1790 | T3: -500 | U3: -8 | V3: -911 | W3: 0.29394531
A4: 86 | B4: 伊賀 | C4: ABO-08BL | D4: ミニホイッスル | E4: ブルー | F4: 527 | G4: 2107 | H4: 796 | I4: =VLOOKUP(C4,'202310-202403出荷数total2403220951'!B:F,5,0) -> 1409 | J4: =VLOOKUP(C4,'出荷数2307～2406total241008110618'!B:F,5,0) -> 1708 | K4: =VLOOKUP(C4,'出荷数2407-2506total250730101950'!B:F,5,0) -> 1865 | L4: =VLOOKUP(C:C,total251219111800!B:F,5,0) -> 474 | M4: 1000 | N4: 1000 | O4: 6744 | P4: 0 | Q4: 0 | R4: 0 | S4: 0 | T4: 0 | U4: 6744 | V4: 5744 | W4: 0.14827995
A5: 107 | B5: 伊賀 | C5: ABO-08PK | D5: ミニホイッスル | E5: ピンク | F5: 3939 | G5: 5966 | H5: 5009 | I5: =VLOOKUP(C5,'202310-202403出荷数total2403220951'!B:F,5,0) -> 6490 | J5: =VLOOKUP(C5,'出荷数2307～2406total241008110618'!B:F,5,0) -> 17931 | K5: =VLOOKUP(C5,'出荷数2407-2506total250730101950'!B:F,5,0) -> 28387 | L5: =VLOOKUP(C:C,total251219111800!B:F,5,0) -> 4495 | N5: =L5 -> 4495 | O5: 27847 | P5: 28180 | Q5: 800 | R5: 0 | S5: 28180 | T5: 0 | U5: 467 | V5: -4028 | W5: 0.080229175
A6: 109 | B6: 伊賀 | C6: APL-4302S | D6: ＬＥＤミニアルミライト | F6: 1094 | G6: 3475 | H6: 834 | I6: =VLOOKUP(C6,'202310-202403出荷数total2403220951'!B:F,5,0) -> 444 | J6: =VLOOKUP(C6,'出荷数2307～2406total241008110618'!B:F,5,0) -> 789 | K6: =VLOOKUP(C6,'出荷数2407-2506total250730101950'!B:F,5,0) -> 232 | L6: =VLOOKUP(C:C,total251219111800!B:F,5,0) -> 177 | N6: =L6 -> 177 | O6: 3754 | P6: 0 | Q6: 300 | R6: 0 | S6: 0 | T6: 0 | U6: 4054 | V6: 3877 | W6: 0.047149707
A7: 3 | B7: 伊賀 | C7: ASL-3308SK | D7: ウォールセンサーライト 箱 | E7: しかく | F7: 1 | G7: 0 | H7: 4 | I7: =VLOOKUP(C7,'202310-202403出荷数total2403220951'!B:F,5,0) -> #N/A | J7: =VLOOKUP(C7,'出荷数2307～2406total241008110618'!B:F,5,0) -> #N/A | K7: =VLOOKUP(C7,'出荷数2407-2506total250730101950'!B:F,5,0) -> #N/A | L7: =VLOOKUP(C:C,total251219111800!B:F,5,0) -> #N/A | N7: 0 | O7: 1 | P7: 0 | Q7: 0 | R7: 0 | S7: 0 | T7: 0 | U7: 1 | V7: 1 | W7: 0
A8: 4 | B8: 伊賀 | C8: AHL-3201RD | D8: LEDハンディライト | H8: 2048 | I8: =VLOOKUP(C8,'202310-202403出荷数total2403220951'!B:F,5,0) -> 2098 | J8: =VLOOKUP(C8,'出荷数2307～2406total241008110618'!B:F,5,0) -> 3644 | K8: =VLOOKUP(C8,'出荷数2407-2506total250730101950'!B:F,5,0) -> 2910 | L8: =VLOOKUP(C:C,total251219111800!B:F,5,0) -> 2559 | N8: =L8 -> 2559 | O8: 3061 | P8: 0 | Q8: 0 | R8: 0 | S8: 0 | T8: 0 | U8: 3061 | V8: 502 | W8: 0.83600131
A9: 5 | B9: 伊賀 | C9: AHL-3201WH | D9: LEDハンディライト | H9: 116 | I9: =VLOOKUP(C9,'202310-202403出荷数total2403220951'!B:F,5,0) -> 220 | J9: =VLOOKUP(C9,'出荷数2307～2406total241008110618'!B:F,5,0) -> 378 | K9: =VLOOKUP(C9,'出荷数2407-2506total250730101950'!B:F,5,0) -> 2016 | L9: =VLOOKUP(C:C,total251219111800!B:F,5,0) -> 281 | M9: 1000 | N9: 1000 | O9: 5183 | P9: 0 | Q9: 0 | R9: 0 | S9: 0 | T9: 0 | U9: 5183 | V9: 4183 | W9: 0.19293845
A10: 6 | B10: 伊賀 | C10: AHL-1400 | D10: LED強力ライト | H10: 15126 | I10: =VLOOKUP(C10,'202310-202403出荷数total2403220951'!B:F,5,0) -> 9163 | J10: =VLOOKUP(C10,'出荷数2307～2406total241008110618'!B:F,5,0) -> 19757 | K10: =VLOOKUP(C10,'出荷数2407-2506total250730101950'!B:F,5,0) -> 20812 | L10: =VLOOKUP(C:C,total251219111800!B:F,5,0) -> 4356 | N10: =L10 -> 4356 | O10: 1838 | P10: 17595 | Q10: 0 | R10: 0 | S10: 17425 | T10: 170 | U10: -15587 | V10: -19943 | W10: 0.22415479
